Workbook
Name cbo_range: OFFSET(#REF!,0,3,#REF!,1)
Name cbo_range: OFFSET(#REF!,0,3,#REF!,1)
Name cbo_range: OFFSET(#REF!,0,3,#REF!,1)
Name cbo_range: OFFSET(#REF!,0,3,#REF!,1)
Name cbo_range: OFFSET(#REF!,0,3,#REF!,1)
Name cbo_range: OFFSET(#REF!,0,3,#REF!,1)
Name cbo_range: OFFSET(#REF!,0,3,#REF!,1)
Name cbo_range: OFFSET(#REF!,0,3,#REF!,1)
Name cbo_range: OFFSET(#REF!,0,3,#REF!,1)
Name cbo_range: OFFSET(#REF!,0,3,#REF!,1)
Name cbo_range: OFFSET(#REF!,0,3,#REF!,1)
Name date_range: OFFSET(#REF!,0,0,#REF!,1)
Name date_range: OFFSET(#REF!,0,0,#REF!,1)
Name date_range: OFFSET(#REF!,0,0,#REF!,1)
Name date_range: OFFSET(#REF!,0,0,#REF!,1)
Name date_range: OFFSET(#REF!,0,0,#REF!,1)
Name date_range: OFFSET(#REF!,0,0,#REF!,1)
Name date_range: OFFSET(#REF!,0,0,#REF!,1)
Name date_range: OFFSET(#REF!,0,0,#REF!,1)
Name date_range: OFFSET(#REF!,0,0,#REF!,1)
Name date_range: OFFSET(#REF!,0,0,#REF!,1)
Name date_range: OFFSET(#REF!,0,0,#REF!,1)
Name jwi_range: OFFSET(#REF!,0,2,#REF!,1)
Name jwi_range: OFFSET(#REF!,0,2,#REF!,1)
Name jwi_range: OFFSET(#REF!,0,2,#REF!,1)
Name jwi_range: OFFSET(#REF!,0,2,#REF!,1)
Name jwi_range: OFFSET(#REF!,0,2,#REF!,1)
Name jwi_range: OFFSET(#REF!,0,2,#REF!,1)
Name jwi_range: OFFSET(#REF!,0,2,#REF!,1)
Name jwi_range: OFFSET(#REF!,0,2,#REF!,1)
Name jwi_range: OFFSET(#REF!,0,2,#REF!,1)
Name jwi_range: OFFSET(#REF!,0,2,#REF!,1)
Name jwi_range: OFFSET(#REF!,0,2,#REF!,1)
Name jwu_range: OFFSET(#REF!,0,1,#REF!,1)
Name jwu_range: OFFSET(#REF!,0,1,#REF!,1)
Name jwu_range: OFFSET(#REF!,0,1,#REF!,1)
Name jwu_range: OFFSET(#REF!,0,1,#REF!,1)
Name jwu_range: OFFSET(#REF!,0,1,#REF!,1)
Name jwu_range: OFFSET(#REF!,0,1,#REF!,1)
Name jwu_range: OFFSET(#REF!,0,1,#REF!,1)
Name jwu_range: OFFSET(#REF!,0,1,#REF!,1)
Name jwu_range: OFFSET(#REF!,0,1,#REF!,1)
Name jwu_range: OFFSET(#REF!,0,1,#REF!,1)
Name jwu_range: OFFSET(#REF!,0,1,#REF!,1)
Name mst_range: OFFSET(#REF!,0,7,#REF!,1)
Name mst_range: OFFSET(#REF!,0,7,#REF!,1)
Name mst_range: OFFSET(#REF!,0,7,#REF!,1)
Name mst_range: OFFSET(#REF!,0,7,#REF!,1)
Name mst_range: OFFSET(#REF!,0,7,#REF!,1)
Name mst_range: OFFSET(#REF!,0,7,#REF!,1)
Name mst_range: OFFSET(#REF!,0,7,#REF!,1)
Name mst_range: OFFSET(#REF!,0,7,#REF!,1)
Name mst_range: OFFSET(#REF!,0,7,#REF!,1)
Name mst_range: OFFSET(#REF!,0,7,#REF!,1)
Name mst_range: OFFSET(#REF!,0,7,#REF!,1)
Name pivot_range: OFFSET(Participation!#REF!,0,0,Participation!#REF!,9)
Name pivot_range: OFFSET('Stats 2017'!$M$23,0,0,'Stats 2017'!$U$17,9)
Name pivot_range: OFFSET('Stats 2018'!$M$23,0,0,'Stats 2018'!$U$17,9)
Name pivot_range: OFFSET('Stats 2019'!$M$23,0,0,'Stats 2019'!$T$17,9)
Name pivot_range: OFFSET('Stats 2021'!$M$23,0,0,'Stats 2021'!$T$17,9)

Sheet Graphs
C1: ='Stats 2020'!O18 -> JWU | D1: ='Stats 2020'!P18 -> CBO | E1: ='Stats 2020'!Q18 -> PKN | F1: ='Stats 2020'!R18 -> YMI | G1: ='Stats 2020'!S18 -> SJU | H1: ='Stats 2020'!T18 -> MST | I1: =C1 -> JWU | J1: =D1 -> CBO | K1: =E1 -> PKN | L1: =F1 -> YMI | M1: =G1 -> SJU | N1: =H1 -> MST | Q1: =C1 -> JWU | R1: =D1 -> CBO | S1: =E1 -> PKN | T1: =F1 -> YMI | U1: =G1 -> SJU | V1: MSO | Y1: =Q1 -> JWU | Z1: =R1 -> CBO | AA1: =S1 -> PKN | AB1: =T1 -> YMI | AC1: =U1 -> SJU | AD1: =V1 -> MSO | AE1: Overall | AF1: =Y1 -> JWU | AG1: =Z1 -> CBO | AH1: =AA1 -> PKN | AI1: =AB1 -> YMI | AJ1: =AC1 -> SJU | AK1: =AD1 -> MSO | AL1: =AE1 -> Overall | AO1: Prognose-und-Estimation-Nonprofit-Institute of Safran
A2: =IF(AND((TODAY()-B2)<7,(TODAY()-B2>=0)),B2,NA()) -> #N/A | B2: 43854 | C2: =IF($B2<=TODAY(),SUMIF('Stats 2020'!$M$24:$M$1048576,"<="&Graphs!$B2,'Stats 2020'!O$24:O$1048576),NA()) -> 50 | D2: =IF($B2<=TODAY(),MAX($C2,$E2,$G2,$H2)+11,NA()) -> 61 | E2: =IF($B2<=TODAY(),SUMIF('Stats 2020'!$M$24:$M$1048576,"<="&Graphs!$B2,'Stats 2020'!Q$24:Q$1048576),NA()) -> 50 | F2: =IF($B2<=TODAY(),MAX($C2,$E2,$G2,$H2)+11,NA()) -> 61 | G2: =IF($B2<=TODAY(),SUMIF('Stats 2020'!$M$24:$M$1048576,"<="&Graphs!$B2,'Stats 2020'!S$24:S$1048576),NA()) -> 50 | H2: =IF($B2<=TODAY(),SUMIF('Stats 2020'!$M$24:$M$1048576,"<="&Graphs!$B2,'Stats 2020'!T$24:T$1048576),NA()) -> 50 | I2: =VLOOKUP($A2,$B$1:$H$59,MATCH(I$1,$B$1:$H$1,0),0) -> #N/A | J2: =VLOOKUP($A2,$B$1:$H$59,MATCH(J$1,$B$1:$H$1,0),0) -> #N/A | K2: =VLOOKUP($A2,$B$1:$H$59,MATCH(K$1,$B$1:$H$1,0),0) -> #N/A | L2: =VLOOKUP($A2,$B$1:$H$59,MATCH(L$1,$B$1:$H$1,0),0) -> #N/A | M2: =VLOOKUP($A2,$B$1:$H$59,MATCH(M$1,$B$1:$H$1,0),0) -> #N/A | N2: =VLOOKUP($A2,$B$1:$H$59,MATCH(N$1,$B$1:$H$1,0),0) -> #N/A | P2: =B2 -> 43854 | Q2: =VLOOKUP($B2,'Stats 2020'!$D$25:$J$200,MATCH(Graphs!Q$1,'Stats 2020'!$D$18:$J$18,0),0) -> 1 | R2: =VLOOKUP($B2,'Stats 2020'!$D$25:$J$200,MATCH(Graphs!R$1,'Stats 2020'!$D$18:$J$18,0),0) | S2: =VLOOKUP($B2,'Stats 2020'!$D$25:$J$200,MATCH(Graphs!S$1,'Stats 2020'!$D$18:$J$18,0),0) -> 1 | T2: =VLOOKUP($B2,'Stats 2020'!$D$25:$J$200,MATCH(Graphs!T$1,'Stats 2020'!$D$18:$J$18,0),0) | U2: =VLOOKUP($B2,'Stats 2020'!$D$25:$J$200,MATCH(Graphs!U$1,'Stats 2020'!$D$18:$J$18,0),0) -> 1 | V2: =VLOOKUP($B2,'Stats 2020'!$D$25:$J$200,MATCH(Graphs!V$1,'Stats 2020'!$D$18:$J$18,0),0) -> 1 | X2: =B2 -> 43854 | Y2: =SUM(Q$2:Q2)/COUNTA($P$2:$P2) -> 1 | Z2: =SUM(R$2:R2)/COUNTA($P$2:$P2) -> 0 | AA2: =SUM(S$2:S2)/COUNTA($P$2:$P2) -> 1 | AB2: =SUM(T$2:T2)/COUNTA($P$2:$P2) -> 0 | AC2: =SUM(U$2:U2)/COUNTA($P$2:$P2) -> 1 | AD2: =SUM(V$2:V2)/COUNTA($P$2:$P2) -> 1 | AE2: =AVERAGE(Y2:AD2) -> 0.66666667 | AF2: =VLOOKUP($A2,$X$1:$AE$59,MATCH(AF$1,$X$1:$AE$1,0),0) -> #N/A | AG2: =VLOOKUP($A2,$X$1:$AE$59,MATCH(AG$1,$X$1:$AE$1,0),0) -> #N/A | AH2: =VLOOKUP($A2,$X$1:$AE$59,MATCH(AH$1,$X$1:$AE$1,0),0) -> #N/A | AI2: =VLOOKUP($A2,$X$1:$AE$59,MATCH(AI$1,$X$1:$AE$1,0),0) -> #N/A | AJ2: =VLOOKUP($A2,$X$1:$AE$59,MATCH(AJ$1,$X$1:$AE$1,0),0) -> #N/A | AK2: =VLOOKUP($A2,$X$1:$AE$59,MATCH(AK$1,$X$1:$AE$1,0),0) -> #N/A | AL2: =VLOOKUP($A2,$X$1:$AE$59,MATCH(AL$1,$X$1:$AE$1,0),0) -> #N/A | AO2: (PENIS)
A3: =IF(AND((TODAY()-B3)<7,(TODAY()-B3>=0)),B3,NA()) -> #N/A | B3: =B2+7 -> 43861 | C3: =IF($B3<=TODAY(),SUMIF('Stats 2020'!$M$24:$M$1048576,"<="&Graphs!$B3,'Stats 2020'!O$24:O$1048576),NA()) -> 50 | D3: =IF($B3<=TODAY(),MAX($C3,$E3,$G3,$H3)+11,NA()) -> 72 | E3: =IF($B3<=TODAY(),SUMIF('Stats 2020'!$M$24:$M$1048576,"<="&Graphs!$B3,'Stats 2020'!Q$24:Q$1048576),NA()) -> 50 | F3: =IF($B3<=TODAY(),MAX($C3,$E3,$G3,$H3)+11,NA()) -> 72 | G3: =IF($B3<=TODAY(),SUMIF('Stats 2020'!$M$24:$M$1048576,"<="&Graphs!$B3,'Stats 2020'!S$24:S$1048576),NA()) -> 61 | H3: =IF($B3<=TODAY(),SUMIF('Stats 2020'!$M$24:$M$1048576,"<="&Graphs!$B3,'Stats 2020'!T$24:T$1048576),NA()) -> 50 | I3: =VLOOKUP($A3,$B$1:$H$59,MATCH(I$1,$B$1:$H$1,0),0) -> #N/A | J3: =VLOOKUP($A3,$B$1:$H$59,MATCH(J$1,$B$1:$H$1,0),0) -> #N/A | K3: =VLOOKUP($A3,$B$1:$H$59,MATCH(K$1,$B$1:$H$1,0),0) -> #N/A | L3: =VLOOKUP($A3,$B$1:$H$59,MATCH(L$1,$B$1:$H$1,0),0) -> #N/A | M3: =VLOOKUP($A3,$B$1:$H$59,MATCH(M$1,$B$1:$H$1,0),0) -> #N/A | N3: =VLOOKUP($A3,$B$1:$H$59,MATCH(N$1,$B$1:$H$1,0),0) -> #N/A | P3: =B3 -> 43861 | Q3: =VLOOKUP($B3,'Stats 2020'!$D$25:$J$200,MATCH(Graphs!Q$1,'Stats 2020'!$D$18:$J$18,0),0) -> 1 | R3: =VLOOKUP($B3,'Stats 2020'!$D$25:$J$200,MATCH(Graphs!R$1,'Stats 2020'!$D$18:$J$18,0),0) | S3: =VLOOKUP($B3,'Stats 2020'!$D$25:$J$200,MATCH(Graphs!S$1,'Stats 2020'!$D$18:$J$18,0),0) -> 1 | T3: =VLOOKUP($B3,'Stats 2020'!$D$25:$J$200,MATCH(Graphs!T$1,'Stats 2020'!$D$18:$J$18,0),0) | U3: =VLOOKUP($B3,'Stats 2020'!$D$25:$J$200,MATCH(Graphs!U$1,'Stats 2020'!$D$18:$J$18,0),0) -> 0 | V3: =VLOOKUP($B3,'Stats 2020'!$D$25:$J$200,MATCH(Graphs!V$1,'Stats 2020'!$D$18:$J$18,0),0) -> 1 | X3: =B3 -> 43861 | Y3: =SUM(Q$2:Q3)/COUNTA($P$2:$P3) -> 1 | Z3: =SUM(R$2:R3)/COUNTA($P$2:$P3) -> 0 | AA3: =SUM(S$2:S3)/COUNTA($P$2:$P3) -> 1 | AB3: =SUM(T$2:T3)/COUNTA($P$2:$P3) -> 0 | AC3: =SUM(U$2:U3)/COUNTA($P$2:$P3) -> 0.5 | AD3: =SUM(V$2:V3)/COUNTA($P$2:$P3) -> 1 | AE3: =AVERAGE(Y3:AD3) -> 0.58333333 | AF3: =VLOOKUP($A3,$X$1:$AE$59,MATCH(AF$1,$X$1:$AE$1,0),0) -> #N/A | AG3: =VLOOKUP($A3,$X$1:$AE$59,MATCH(AG$1,$X$1:$AE$1,0),0) -> #N/A | AH3: =VLOOKUP($A3,$X$1:$AE$59,MATCH(AH$1,$X$1:$AE$1,0),0) -> #N/A | AI3: =VLOOKUP($A3,$X$1:$AE$59,MATCH(AI$1,$X$1:$AE$1,0),0) -> #N/A | AJ3: =VLOOKUP($A3,$X$1:$AE$59,MATCH(AJ$1,$X$1:$AE$1,0),0) -> #N/A | AK3: =VLOOKUP($A3,$X$1:$AE$59,MATCH(AK$1,$X$1:$AE$1,0),0) -> #N/A | AL3: =VLOOKUP($A3,$X$1:$AE$59,MATCH(AL$1,$X$1:$AE$1,0),0) -> #N/A
A4: =IF(AND((TODAY()-B4)<7,(TODAY()-B4>=0)),B4,NA()) -> #N/A | B4: =B3+7 -> 43868 | C4: =IF($B4<=TODAY(),SUMIF('Stats 2020'!$M$24:$M$1048576,"<="&Graphs!$B4,'Stats 2020'!O$24:O$1048576),NA()) -> 61 | D4: =IF($B4<=TODAY(),MAX($C4,$E4,$G4,$H4)+11,NA()) -> 83 | E4: =IF($B4<=TODAY(),SUMIF('Stats 2020'!$M$24:$M$1048576,"<="&Graphs!$B4,'Stats 2020'!Q$24:Q$1048576),NA()) -> 50 | F4: =IF($B4<=TODAY(),MAX($C4,$E4,$G4,$H4)+11,NA()) -> 83 | G4: =IF($B4<=TODAY(),SUMIF('Stats 2020'!$M$24:$M$1048576,"<="&Graphs!$B4,'Stats 2020'!S$24:S$1048576),NA()) -> 72 | H4: =IF($B4<=TODAY(),SUMIF('Stats 2020'!$M$24:$M$1048576,"<="&Graphs!$B4,'Stats 2020'!T$24:T$1048576),NA()) -> 50 | I4: =VLOOKUP($A4,$B$1:$H$59,MATCH(I$1,$B$1:$H$1,0),0) -> #N/A | J4: =VLOOKUP($A4,$B$1:$H$59,MATCH(J$1,$B$1:$H$1,0),0) -> #N/A | K4: =VLOOKUP($A4,$B$1:$H$59,MATCH(K$1,$B$1:$H$1,0),0) -> #N/A | L4: =VLOOKUP($A4,$B$1:$H$59,MATCH(L$1,$B$1:$H$1,0),0) -> #N/A | M4: =VLOOKUP($A4,$B$1:$H$59,MATCH(M$1,$B$1:$H$1,0),0) -> #N/A | N4: =VLOOKUP($A4,$B$1:$H$59,MATCH(N$1,$B$1:$H$1,0),0) -> #N/A | P4: =B4 -> 43868 | Q4: =VLOOKUP($B4,'Stats 2020'!$D$25:$J$200,MATCH(Graphs!Q$1,'Stats 2020'!$D$18:$J$18,0),0) -> 0 | R4: =VLOOKUP($B4,'Stats 2020'!$D$25:$J$200,MATCH(Graphs!R$1,'Stats 2020'!$D$18:$J$18,0),0) | S4: =VLOOKUP($B4,'Stats 2020'!$D$25:$J$200,MATCH(Graphs!S$1,'Stats 2020'!$D$18:$J$18,0),0) -> 1 | T4: =VLOOKUP($B4,'Stats 2020'!$D$25:$J$200,MATCH(Graphs!T$1,'Stats 2020'!$D$18:$J$18,0),0) | U4: =VLOOKUP($B4,'Stats 2020'!$D$25:$J$200,MATCH(Graphs!U$1,'Stats 2020'!$D$18:$J$18,0),0) -> 0 | V4: =VLOOKUP($B4,'Stats 2020'!$D$25:$J$200,MATCH(Graphs!V$1,'Stats 2020'!$D$18:$J$18,0),0) -> 1 | X4: =B4 -> 43868 | Y4: =SUM(Q$2:Q4)/COUNTA($P$2:$P4) -> 0.66666667 | Z4: =SUM(R$2:R4)/COUNTA($P$2:$P4) -> 0 | AA4: =SUM(S$2:S4)/COUNTA($P$2:$P4) -> 1 | AB4: =SUM(T$2:T4)/COUNTA($P$2:$P4) -> 0 | AC4: =SUM(U$2:U4)/COUNTA($P$2:$P4) -> 0.33333333 | AD4: =SUM(V$2:V4)/COUNTA($P$2:$P4) -> 1 | AE4: =AVERAGE(Y4:AD4) -> 0.5 | AF4: =VLOOKUP($A4,$X$1:$AE$59,MATCH(AF$1,$X$1:$AE$1,0),0) -> #N/A | AG4: =VLOOKUP($A4,$X$1:$AE$59,MATCH(AG$1,$X$1:$AE$1,0),0) -> #N/A | AH4: =VLOOKUP($A4,$X$1:$AE$59,MATCH(AH$1,$X$1:$AE$1,0),0) -> #N/A | AI4: =VLOOKUP($A4,$X$1:$AE$59,MATCH(AI$1,$X$1:$AE$1,0),0) -> #N/A | AJ4: =VLOOKUP($A4,$X$1:$AE$59,MATCH(AJ$1,$X$1:$AE$1,0),0) -> #N/A | AK4: =VLOOKUP($A4,$X$1:$AE$59,MATCH(AK$1,$X$1:$AE$1,0),0) -> #N/A | AL4: =VLOOKUP($A4,$X$1:$AE$59,MATCH(AL$1,$X$1:$AE$1,0),0) -> #N/A
A5: =IF(AND((TODAY()-B5)<7,(TODAY()-B5>=0)),B5,NA()) -> #N/A | B5: =B4+7 -> 43875 | C5: =IF($B5<=TODAY(),SUMIF('Stats 2020'!$M$24:$M$1048576,"<="&Graphs!$B5,'Stats 2020'!O$24:O$1048576),NA()) -> 61 | D5: =IF($B5<=TODAY(),MAX($C5,$E5,$G5,$H5)+11,NA()) -> 94 | E5: =IF($B5<=TODAY(),SUMIF('Stats 2020'!$M$24:$M$1048576,"<="&Graphs!$B5,'Stats 2020'!Q$24:Q$1048576),NA()) -> 50 | F5: =IF($B5<=TODAY(),MAX($C5,$E5,$G5,$H5)+11,NA()) -> 94 | G5: =IF($B5<=TODAY(),SUMIF('Stats 2020'!$M$24:$M$1048576,"<="&Graphs!$B5,'Stats 2020'!S$24:S$1048576),NA()) -> 83 | H5: =IF($B5<=TODAY(),SUMIF('Stats 2020'!$M$24:$M$1048576,"<="&Graphs!$B5,'Stats 2020'!T$24:T$1048576),NA()) -> 50 | I5: =VLOOKUP($A5,$B$1:$H$59,MATCH(I$1,$B$1:$H$1,0),0) -> #N/A | J5: =VLOOKUP($A5,$B$1:$H$59,MATCH(J$1,$B$1:$H$1,0),0) -> #N/A | K5: =VLOOKUP($A5,$B$1:$H$59,MATCH(K$1,$B$1:$H$1,0),0) -> #N/A | L5: =VLOOKUP($A5,$B$1:$H$59,MATCH(L$1,$B$1:$H$1,0),0) -> #N/A | M5: =VLOOKUP($A5,$B$1:$H$59,MATCH(M$1,$B$1:$H$1,0),0) -> #N/A | N5: =VLOOKUP($A5,$B$1:$H$59,MATCH(N$1,$B$1:$H$1,0),0) -> #N/A | P5: =B5 -> 43875 | Q5: =VLOOKUP($B5,'Stats 2020'!$D$25:$J$200,MATCH(Graphs!Q$1,'Stats 2020'!$D$18:$J$18,0),0) -> 1 | R5: =VLOOKUP($B5,'Stats 2020'!$D$25:$J$200,MATCH(Graphs!R$1,'Stats 2020'!$D$18:$J$18,0),0) | S5: =VLOOKUP($B5,'Stats 2020'!$D$25:$J$200,MATCH(Graphs!S$1,'Stats 2020'!$D$18:$J$18,0),0) -> 1 | T5: =VLOOKUP($B5,'Stats 2020'!$D$25:$J$200,MATCH(Graphs!T$1,'Stats 2020'!$D$18:$J$18,0),0) | U5: =VLOOKUP($B5,'Stats 2020'!$D$25:$J$200,MATCH(Graphs!U$1,'Stats 2020'!$D$18:$J$18,0),0) -> 0 | V5: =VLOOKUP($B5,'Stats 2020'!$D$25:$J$200,MATCH(Graphs!V$1,'Stats 2020'!$D$18:$J$18,0),0) -> 1 | X5: =B5 -> 43875 | Y5: =SUM(Q$2:Q5)/COUNTA($P$2:$P5) -> 0.75 | Z5: =SUM(R$2:R5)/COUNTA($P$2:$P5) -> 0 | AA5: =SUM(S$2:S5)/COUNTA($P$2:$P5) -> 1 | AB5: =SUM(T$2:T5)/COUNTA($P$2:$P5) -> 0 | AC5: =SUM(U$2:U5)/COUNTA($P$2:$P5) -> 0.25 | AD5: =SUM(V$2:V5)/COUNTA($P$2:$P5) -> 1 | AE5: =AVERAGE(Y5:AD5) -> 0.5 | AF5: =VLOOKUP($A5,$X$1:$AE$59,MATCH(AF$1,$X$1:$AE$1,0),0) -> #N/A | AG5: =VLOOKUP($A5,$X$1:$AE$59,MATCH(AG$1,$X$1:$AE$1,0),0) -> #N/A | AH5: =VLOOKUP($A5,$X$1:$AE$59,MATCH(AH$1,$X$1:$AE$1,0),0) -> #N/A | AI5: =VLOOKUP($A5,$X$1:$AE$59,MATCH(AI$1,$X$1:$AE$1,0),0) -> #N/A | AJ5: =VLOOKUP($A5,$X$1:$AE$59,MATCH(AJ$1,$X$1:$AE$1,0),0) -> #N/A | AK5: =VLOOKUP($A5,$X$1:$AE$59,MATCH(AK$1,$X$1:$AE$1,0),0) -> #N/A | AL5: =VLOOKUP($A5,$X$1:$AE$59,MATCH(AL$1,$X$1:$AE$1,0),0) -> #N/A | AO5: 1. YMI (203.8%)
A6: =IF(AND((TODAY()-B6)<7,(TODAY()-B6>=0)),B6,NA()) -> #N/A | B6: =B5+7 -> 43882 | C6: =IF($B6<=TODAY(),SUMIF('Stats 2020'!$M$24:$M$1048576,"<="&Graphs!$B6,'Stats 2020'!O$24:O$1048576),NA()) -> 61 | D6: =IF($B6<=TODAY(),MAX($C6,$E6,$G6,$H6)+11,NA()) -> 94 | E6: =IF($B6<=TODAY(),SUMIF('Stats 2020'!$M$24:$M$1048576,"<="&Graphs!$B6,'Stats 2020'!Q$24:Q$1048576),NA()) -> 50 | F6: =IF($B6<=TODAY(),MAX($C6,$E6,$G6,$H6)+11,NA()) -> 94 | G6: =IF($B6<=TODAY(),SUMIF('Stats 2020'!$M$24:$M$1048576,"<="&Graphs!$B6,'Stats 2020'!S$24:S$1048576),NA()) -> 83 | H6: =IF($B6<=TODAY(),SUMIF('Stats 2020'!$M$24:$M$1048576,"<="&Graphs!$B6,'Stats 2020'!T$24:T$1048576),NA()) -> 50 | I6: =VLOOKUP($A6,$B$1:$H$59,MATCH(I$1,$B$1:$H$1,0),0) -> #N/A | J6: =VLOOKUP($A6,$B$1:$H$59,MATCH(J$1,$B$1:$H$1,0),0) -> #N/A | K6: =VLOOKUP($A6,$B$1:$H$59,MATCH(K$1,$B$1:$H$1,0),0) -> #N/A | L6: =VLOOKUP($A6,$B$1:$H$59,MATCH(L$1,$B$1:$H$1,0),0) -> #N/A | M6: =VLOOKUP($A6,$B$1:$H$59,MATCH(M$1,$B$1:$H$1,0),0) -> #N/A | N6: =VLOOKUP($A6,$B$1:$H$59,MATCH(N$1,$B$1:$H$1,0),0) -> #N/A | P6: =B6 -> 43882 | Q6: =VLOOKUP($B6,'Stats 2020'!$D$25:$J$200,MATCH(Graphs!Q$1,'Stats 2020'!$D$18:$J$18,0),0) -> 1 | R6: =VLOOKUP($B6,'Stats 2020'!$D$25:$J$200,MATCH(Graphs!R$1,'Stats 2020'!$D$18:$J$18,0),0) | S6: =VLOOKUP($B6,'Stats 2020'!$D$25:$J$200,MATCH(Graphs!S$1,'Stats 2020'!$D$18:$J$18,0),0) -> 1 | T6: =VLOOKUP($B6,'Stats 2020'!$D$25:$J$200,MATCH(Graphs!T$1,'Stats 2020'!$D$18:$J$18,0),0) | U6: =VLOOKUP($B6,'Stats 2020'!$D$25:$J$200,MATCH(Graphs!U$1,'Stats 2020'!$D$18:$J$18,0),0) -> 1 | V6: =VLOOKUP($B6,'Stats 2020'!$D$25:$J$200,MATCH(Graphs!V$1,'Stats 2020'!$D$18:$J$18,0),0) -> 1 | X6: =B6 -> 43882 | Y6: =SUM(Q$2:Q6)/COUNTA($P$2:$P6) -> 0.8 | Z6: =SUM(R$2:R6)/COUNTA($P$2:$P6) -> 0 | AA6: =SUM(S$2:S6)/COUNTA($P$2:$P6) -> 1 | AB6: =SUM(T$2:T6)/COUNTA($P$2:$P6) -> 0 | AC6: =SUM(U$2:U6)/COUNTA($P$2:$P6) -> 0.4 | AD6: =SUM(V$2:V6)/COUNTA($P$2:$P6) -> 1 | AE6: =AVERAGE(Y6:AD6) -> 0.53333333 | AF6: =VLOOKUP($A6,$X$1:$AE$59,MATCH(AF$1,$X$1:$AE$1,0),0) -> #N/A | AG6: =VLOOKUP($A6,$X$1:$AE$59,MATCH(AG$1,$X$1:$AE$1,0),0) -> #N/A | AH6: =VLOOKUP($A6,$X$1:$AE$59,MATCH(AH$1,$X$1:$AE$1,0),0) -> #N/A | AI6: =VLOOKUP($A6,$X$1:$AE$59,MATCH(AI$1,$X$1:$AE$1,0),0) -> #N/A | AJ6: =VLOOKUP($A6,$X$1:$AE$59,MATCH(AJ$1,$X$1:$AE$1,0),0) -> #N/A | AK6: =VLOOKUP($A6,$X$1:$AE$59,MATCH(AK$1,$X$1:$AE$1,0),0) -> #N/A | AL6: =VLOOKUP($A6,$X$1:$AE$59,MATCH(AL$1,$X$1:$AE$1,0),0) -> #N/A | AO6: 2. SJU (134.6%)
A7: =IF(AND((TODAY()-B7)<7,(TODAY()-B7>=0)),B7,NA()) -> #N/A | B7: =B6+7 -> 43889 | C7: =IF($B7<=TODAY(),SUMIF('Stats 2020'!$M$24:$M$1048576,"<="&Graphs!$B7,'Stats 2020'!O$24:O$1048576),NA()) -> 63.75 | D7: =IF($B7<=TODAY(),MAX($C7,$E7,$G7,$H7)+11,NA()) -> 96.75 | E7: =IF($B7<=TODAY(),SUMIF('Stats 2020'!$M$24:$M$1048576,"<="&Graphs!$B7,'Stats 2020'!Q$24:Q$1048576),NA()) -> 61 | F7: =IF($B7<=TODAY(),MAX($C7,$E7,$G7,$H7)+11,NA()) -> 96.75 | G7: =IF($B7<=TODAY(),SUMIF('Stats 2020'!$M$24:$M$1048576,"<="&Graphs!$B7,'Stats 2020'!S$24:S$1048576),NA()) -> 85.75 | H7: =IF($B7<=TODAY(),SUMIF('Stats 2020'!$M$24:$M$1048576,"<="&Graphs!$B7,'Stats 2020'!T$24:T$1048576),NA()) -> 61 | I7: =VLOOKUP($A7,$B$1:$H$59,MATCH(I$1,$B$1:$H$1,0),0) -> #N/A | J7: =VLOOKUP($A7,$B$1:$H$59,MATCH(J$1,$B$1:$H$1,0),0) -> #N/A | K7: =VLOOKUP($A7,$B$1:$H$59,MATCH(K$1,$B$1:$H$1,0),0) -> #N/A | L7: =VLOOKUP($A7,$B$1:$H$59,MATCH(L$1,$B$1:$H$1,0),0) -> #N/A | M7: =VLOOKUP($A7,$B$1:$H$59,MATCH(M$1,$B$1:$H$1,0),0) -> #N/A | N7: =VLOOKUP($A7,$B$1:$H$59,MATCH(N$1,$B$1:$H$1,0),0) -> #N/A | P7: =B7 -> 43889 | Q7: =VLOOKUP($B7,'Stats 2020'!$D$25:$J$200,MATCH(Graphs!Q$1,'Stats 2020'!$D$18:$J$18,0),0) -> 1 | R7: =VLOOKUP($B7,'Stats 2020'!$D$25:$J$200,MATCH(Graphs!R$1,'Stats 2020'!$D$18:$J$18,0),0) | S7: =VLOOKUP($B7,'Stats 2020'!$D$25:$J$200,MATCH(Graphs!S$1,'Stats 2020'!$D$18:$J$18,0),0) -> 0 | T7: =VLOOKUP($B7,'Stats 2020'!$D$25:$J$200,MATCH(Graphs!T$1,'Stats 2020'!$D$18:$J$18,0),0) | U7: =VLOOKUP($B7,'Stats 2020'!$D$25:$J$200,MATCH(Graphs!U$1,'Stats 2020'!$D$18:$J$18,0),0) -> 1 | V7: =VLOOKUP($B7,'Stats 2020'!$D$25:$J$200,MATCH(Graphs!V$1,'Stats 2020'!$D$18:$J$18,0),0) -> 0 | X7: =B7 -> 43889 | Y7: =SUM(Q$2:Q7)/COUNTA($P$2:$P7) -> 0.83333333 | Z7: =SUM(R$2:R7)/COUNTA($P$2:$P7) -> 0 | AA7: =SUM(S$2:S7)/COUNTA($P$2:$P7) -> 0.83333333 | AB7: =SUM(T$2:T7)/COUNTA($P$2:$P7) -> 0 | AC7: =SUM(U$2:U7)/COUNTA($P$2:$P7) -> 0.5 | AD7: =SUM(V$2:V7)/COUNTA($P$2:$P7) -> 0.83333333 | AE7: =AVERAGE(Y7:AD7) -> 0.5 | AF7: =VLOOKUP($A7,$X$1:$AE$59,MATCH(AF$1,$X$1:$AE$1,0),0) -> #N/A | AG7: =VLOOKUP($A7,$X$1:$AE$59,MATCH(AG$1,$X$1:$AE$1,0),0) -> #N/A | AH7: =VLOOKUP($A7,$X$1:$AE$59,MATCH(AH$1,$X$1:$AE$1,0),0) -> #N/A | AI7: =VLOOKUP($A7,$X$1:$AE$59,MATCH(AI$1,$X$1:$AE$1,0),0) -> #N/A | AJ7: =VLOOKUP($A7,$X$1:$AE$59,MATCH(AJ$1,$X$1:$AE$1,0),0) -> #N/A | AK7: =VLOOKUP($A7,$X$1:$AE$59,MATCH(AK$1,$X$1:$AE$1,0),0) -> #N/A | AL7: =VLOOKUP($A7,$X$1:$AE$59,MATCH(AL$1,$X$1:$AE$1,0),0) -> #N/A | AO7: 3. PKN (123.1%)
A8: =IF(AND((TODAY()-B8)<7,(TODAY()-B8>=0)),B8,NA()) -> #N/A | B8: =B7+7 -> 43896 | C8: =IF($B8<=TODAY(),SUMIF('Stats 2020'!$M$24:$M$1048576,"<="&Graphs!$B8,'Stats 2020'!O$24:O$1048576),NA()) -> 63.75 | D8: =IF($B8<=TODAY(),MAX($C8,$E8,$G8,$H8)+11,NA()) -> 96.75 | E8: =IF($B8<=TODAY(),SUMIF('Stats 2020'!$M$24:$M$1048576,"<="&Graphs!$B8,'Stats 2020'!Q$24:Q$1048576),NA()) -> 61 | F8: =IF($B8<=TODAY(),MAX($C8,$E8,$G8,$H8)+11,NA()) -> 96.75 | G8: =IF($B8<=TODAY(),SUMIF('Stats 2020'!$M$24:$M$1048576,"<="&Graphs!$B8,'Stats 2020'!S$24:S$1048576),NA()) -> 85.75 | H8: =IF($B8<=TODAY(),SUMIF('Stats 2020'!$M$24:$M$1048576,"<="&Graphs!$B8,'Stats 2020'!T$24:T$1048576),NA()) -> 61 | I8: =VLOOKUP($A8,$B$1:$H$59,MATCH(I$1,$B$1:$H$1,0),0) -> #N/A | J8: =VLOOKUP($A8,$B$1:$H$59,MATCH(J$1,$B$1:$H$1,0),0) -> #N/A | K8: =VLOOKUP($A8,$B$1:$H$59,MATCH(K$1,$B$1:$H$1,0),0) -> #N/A | L8: =VLOOKUP($A8,$B$1:$H$59,MATCH(L$1,$B$1:$H$1,0),0) -> #N/A | M8: =VLOOKUP($A8,$B$1:$H$59,MATCH(M$1,$B$1:$H$1,0),0) -> #N/A | N8: =VLOOKUP($A8,$B$1:$H$59,MATCH(N$1,$B$1:$H$1,0),0) -> #N/A | P8: =B8 -> 43896 | Q8: =VLOOKUP($B8,'Stats 2020'!$D$25:$J$200,MATCH(Graphs!Q$1,'Stats 2020'!$D$18:$J$18,0),0) -> 1 | R8: =VLOOKUP($B8,'Stats 2020'!$D$25:$J$200,MATCH(Graphs!R$1,'Stats 2020'!$D$18:$J$18,0),0) | S8: =VLOOKUP($B8,'Stats 2020'!$D$25:$J$200,MATCH(Graphs!S$1,'Stats 2020'!$D$18:$J$18,0),0) -> 1 | T8: =VLOOKUP($B8,'Stats 2020'!$D$25:$J$200,MATCH(Graphs!T$1,'Stats 2020'!$D$18:$J$18,0),0) | U8: =VLOOKUP($B8,'Stats 2020'!$D$25:$J$200,MATCH(Graphs!U$1,'Stats 2020'!$D$18:$J$18,0),0) -> 1 | V8: =VLOOKUP($B8,'Stats 2020'!$D$25:$J$200,MATCH(Graphs!V$1,'Stats 2020'!$D$18:$J$18,0),0) -> 1 | X8: =B8 -> 43896 | Y8: =SUM(Q$2:Q8)/COUNTA($P$2:$P8) -> 0.85714286 | Z8: =SUM(R$2:R8)/COUNTA($P$2:$P8) -> 0 | AA8: =SUM(S$2:S8)/COUNTA($P$2:$P8) -> 0.85714286 | AB8: =SUM(T$2:T8)/COUNTA($P$2:$P8) -> 0 | AC8: =SUM(U$2:U8)/COUNTA($P$2:$P8) -> 0.57142857 | AD8: =SUM(V$2:V8)/COUNTA($P$2:$P8) -> 0.85714286 | AE8: =AVERAGE(Y8:AD8) -> 0.52380952 | AF8: =VLOOKUP($A8,$X$1:$AE$59,MATCH(AF$1,$X$1:$AE$1,0),0) -> #N/A | AG8: =VLOOKUP($A8,$X$1:$AE$59,MATCH(AG$1,$X$1:$AE$1,0),0) -> #N/A | AH8: =VLOOKUP($A8,$X$1:$AE$59,MATCH(AH$1,$X$1:$AE$1,0),0) -> #N/A | AI8: =VLOOKUP($A8,$X$1:$AE$59,MATCH(AI$1,$X$1:$AE$1,0),0) -> #N/A | AJ8: =VLOOKUP($A8,$X$1:$AE$59,MATCH(AJ$1,$X$1:$AE$1,0),0) -> #N/A | AK8: =VLOOKUP($A8,$X$1:$AE$59,MATCH(AK$1,$X$1:$AE$1,0),0) -> #N/A | AL8: =VLOOKUP($A8,$X$1:$AE$59,MATCH(AL$1,$X$1:$AE$1,0),0) -> #N/A | AO8: 4. MSO/MST und JWU (je 116.5%)
A9: =IF(AND((TODAY()-B9)<7,(TODAY()-B9>=0)),B9,NA()) -> #N/A | B9: =B8+7 -> 43903 | C9: =IF($B9<=TODAY(),SUMIF('Stats 2020'!$M$24:$M$1048576,"<="&Graphs!$B9,'Stats 2020'!O$24:O$1048576),NA()) -> 63.75 | D9: =IF($B9<=TODAY(),MAX($C9,$E9,$G9,$H9)+11+16.5,NA()) -> 113.25 | E9: =IF($B9<=TODAY(),SUMIF('Stats 2020'!$M$24:$M$1048576,"<="&Graphs!$B9,'Stats 2020'!Q$24:Q$1048576),NA()) -> 72 | F9: =IF($B9<=TODAY(),MAX($C9,$E9,$G9,$H9)+11+16.5,NA()) -> 113.25 | G9: =IF($B9<=TODAY(),SUMIF('Stats 2020'!$M$24:$M$1048576,"<="&Graphs!$B9,'Stats 2020'!S$24:S$1048576),NA()) -> 85.75 | H9: =IF($B9<=TODAY(),SUMIF('Stats 2020'!$M$24:$M$1048576,"<="&Graphs!$B9,'Stats 2020'!T$24:T$1048576),NA()) -> 61 | I9: =VLOOKUP($A9,$B$1:$H$59,MATCH(I$1,$B$1:$H$1,0),0) -> #N/A | J9: =VLOOKUP($A9,$B$1:$H$59,MATCH(J$1,$B$1:$H$1,0),0) -> #N/A | K9: =VLOOKUP($A9,$B$1:$H$59,MATCH(K$1,$B$1:$H$1,0),0) -> #N/A | L9: =VLOOKUP($A9,$B$1:$H$59,MATCH(L$1,$B$1:$H$1,0),0) -> #N/A | M9: =VLOOKUP($A9,$B$1:$H$59,MATCH(M$1,$B$1:$H$1,0),0) -> #N/A | N9: =VLOOKUP($A9,$B$1:$H$59,MATCH(N$1,$B$1:$H$1,0),0) -> #N/A | P9: =B9 -> 43903 | Q9: =VLOOKUP($B9,'Stats 2020'!$D$25:$J$200,MATCH(Graphs!Q$1,'Stats 2020'!$D$18:$J$18,0),0) -> 1 | R9: =VLOOKUP($B9,'Stats 2020'!$D$25:$J$200,MATCH(Graphs!R$1,'Stats 2020'!$D$18:$J$18,0),0) | S9: =VLOOKUP($B9,'Stats 2020'!$D$25:$J$200,MATCH(Graphs!S$1,'Stats 2020'!$D$18:$J$18,0),0) -> 0 | T9: =VLOOKUP($B9,'Stats 2020'!$D$25:$J$200,MATCH(Graphs!T$1,'Stats 2020'!$D$18:$J$18,0),0) | U9: =VLOOKUP($B9,'Stats 2020'!$D$25:$J$200,MATCH(Graphs!U$1,'Stats 2020'!$D$18:$J$18,0),0) -> 1 | V9: =VLOOKUP($B9,'Stats 2020'!$D$25:$J$200,MATCH(Graphs!V$1,'Stats 2020'!$D$18:$J$18,0),0) -> 1 | X9: =B9 -> 43903 | Y9: =SUM(Q$2:Q9)/COUNTA($P$2:$P9) -> 0.875 | Z9: =SUM(R$2:R9)/COUNTA($P$2:$P9) -> 0 | AA9: =SUM(S$2:S9)/COUNTA($P$2:$P9) -> 0.75 | AB9: =SUM(T$2:T9)/COUNTA($P$2:$P9) -> 0 | AC9: =SUM(U$2:U9)/COUNTA($P$2:$P9) -> 0.625 | AD9: =SUM(V$2:V9)/COUNTA($P$2:$P9) -> 0.875 | AE9: =AVERAGE(Y9:AD9) -> 0.52083333 | AF9: =VLOOKUP($A9,$X$1:$AE$59,MATCH(AF$1,$X$1:$AE$1,0),0) -> #N/A | AG9: =VLOOKUP($A9,$X$1:$AE$59,MATCH(AG$1,$X$1:$AE$1,0),0) -> #N/A | AH9: =VLOOKUP($A9,$X$1:$AE$59,MATCH(AH$1,$X$1:$AE$1,0),0) -> #N/A | AI9: =VLOOKUP($A9,$X$1:$AE$59,MATCH(AI$1,$X$1:$AE$1,0),0) -> #N/A | AJ9: =VLOOKUP($A9,$X$1:$AE$59,MATCH(AJ$1,$X$1:$AE$1,0),0) -> #N/A | AK9: =VLOOKUP($A9,$X$1:$AE$59,MATCH(AK$1,$X$1:$AE$1,0),0) -> #N/A | AL9: =VLOOKUP($A9,$X$1:$AE$59,MATCH(AL$1,$X$1:$AE$1,0),0) -> #N/A | AO9: 5. CBO (-11.5%)
A10: =IF(AND((TODAY()-B10)<7,(TODAY()-B10>=0)),B10,NA()) -> #N/A | B10: =B9+7 -> 43910 | C10: =IF($B10<=TODAY(),SUMIF('Stats 2020'!$M$24:$M$1048576,"<="&Graphs!$B10,'Stats 2020'!O$24:O$1048576),NA()) -> 63.75 | D10: =IF($B10<=TODAY(),MAX($C10,$E10,$G10,$H10)+11+16.5,NA()) -> 113.25 | E10: =IF($B10<=TODAY(),SUMIF('Stats 2020'!$M$24:$M$1048576,"<="&Graphs!$B10,'Stats 2020'!Q$24:Q$1048576),NA()) -> 72 | F10: =IF($B10<=TODAY(),MAX($C10,$E10,$G10,$H10)+11+16.5,NA()) -> 113.25 | G10: =IF($B10<=TODAY(),SUMIF('Stats 2020'!$M$24:$M$1048576,"<="&Graphs!$B10,'Stats 2020'!S$24:S$1048576),NA()) -> 85.75 | H10: =IF($B10<=TODAY(),SUMIF('Stats 2020'!$M$24:$M$1048576,"<="&Graphs!$B10,'Stats 2020'!T$24:T$1048576),NA()) -> 61 | I10: =VLOOKUP($A10,$B$1:$H$59,MATCH(I$1,$B$1:$H$1,0),0) -> #N/A | J10: =VLOOKUP($A10,$B$1:$H$59,MATCH(J$1,$B$1:$H$1,0),0) -> #N/A | K10: =VLOOKUP($A10,$B$1:$H$59,MATCH(K$1,$B$1:$H$1,0),0) -> #N/A | L10: =VLOOKUP($A10,$B$1:$H$59,MATCH(L$1,$B$1:$H$1,0),0) -> #N/A | M10: =VLOOKUP($A10,$B$1:$H$59,MATCH(M$1,$B$1:$H$1,0),0) -> #N/A | N10: =VLOOKUP($A10,$B$1:$H$59,MATCH(N$1,$B$1:$H$1,0),0) -> #N/A | P10: =B10 -> 43910 | Q10: =VLOOKUP($B10,'Stats 2020'!$D$25:$J$200,MATCH(Graphs!Q$1,'Stats 2020'!$D$18:$J$18,0),0) -> 1 | R10: =VLOOKUP($B10,'Stats 2020'!$D$25:$J$200,MATCH(Graphs!R$1,'Stats 2020'!$D$18:$J$18,0),0) | S10: =VLOOKUP($B10,'Stats 2020'!$D$25:$J$200,MATCH(Graphs!S$1,'Stats 2020'!$D$18:$J$18,0),0) -> 1 | T10: =VLOOKUP($B10,'Stats 2020'!$D$25:$J$200,MATCH(Graphs!T$1,'Stats 2020'!$D$18:$J$18,0),0) -> 1 | U10: =VLOOKUP($B10,'Stats 2020'!$D$25:$J$200,MATCH(Graphs!U$1,'Stats 2020'!$D$18:$J$18,0),0) -> 1 | V10: =VLOOKUP($B10,'Stats 2020'!$D$25:$J$200,MATCH(Graphs!V$1,'Stats 2020'!$D$18:$J$18,0),0) -> 1 | X10: =B10 -> 43910 | Y10: =SUM(Q$2:Q10)/COUNTA($P$2:$P10) -> 0.88888889 | Z10: =SUM(R$2:R10)/COUNTA($P$2:$P10) -> 0 | AA10: =SUM(S$2:S10)/COUNTA($P$2:$P10) -> 0.77777778 | AB10: =SUM(T$2:T10)/COUNTA($P$2:$P10) -> 0.11111111 | AC10: =SUM(U$2:U10)/COUNTA($P$2:$P10) -> 0.66666667 | AD10: =SUM(V$2:V10)/COUNTA($P$2:$P10) -> 0.88888889 | AE10: =AVERAGE(Y10:AD10) -> 0.55555556 | AF10: =VLOOKUP($A10,$X$1:$AE$59,MATCH(AF$1,$X$1:$AE$1,0),0) -> #N/A | AG10: =VLOOKUP($A10,$X$1:$AE$59,MATCH(AG$1,$X$1:$AE$1,0),0) -> #N/A | AH10: =VLOOKUP($A10,$X$1:$AE$59,MATCH(AH$1,$X$1:$AE$1,0),0) -> #N/A | AI10: =VLOOKUP($A10,$X$1:$AE$59,MATCH(AI$1,$X$1:$AE$1,0),0) -> #N/A | AJ10: =VLOOKUP($A10,$X$1:$AE$59,MATCH(AJ$1,$X$1:$AE$1,0),0) -> #N/A | AK10: =VLOOKUP($A10,$X$1:$AE$59,MATCH(AK$1,$X$1:$AE$1,0),0) -> #N/A | AL10: =VLOOKUP($A10,$X$1:$AE$59,MATCH(AL$1,$X$1:$AE$1,0),0) -> #N/A
A11: =IF(AND((TODAY()-B11)<7,(TODAY()-B11>=0)),B11,NA()) -> #N/A | B11: =7+B10 -> 43917 | C11: =IF($B11<=TODAY(),SUMIF('Stats 2020'!$M$24:$M$1048576,"<="&Graphs!$B11,'Stats 2020'!O$24:O$1048576),NA()) -> 63.75 | D11: =IF($B11<=TODAY(),MAX($C11,$E11,$G11,$H11)+11+16.5,NA()) -> 113.25 | E11: =IF($B11<=TODAY(),SUMIF('Stats 2020'!$M$24:$M$1048576,"<="&Graphs!$B11,'Stats 2020'!Q$24:Q$1048576),NA()) -> 72 | F11: =IF($B11<=TODAY(),MAX($C11,$E11,$G11,$H11)+11+16.5,NA()) -> 113.25 | G11: =IF($B11<=TODAY(),SUMIF('Stats 2020'!$M$24:$M$1048576,"<="&Graphs!$B11,'Stats 2020'!S$24:S$1048576),NA()) -> 85.75 | H11: =IF($B11<=TODAY(),SUMIF('Stats 2020'!$M$24:$M$1048576,"<="&Graphs!$B11,'Stats 2020'!T$24:T$1048576),NA()) -> 61 | I11: =VLOOKUP($A11,$B$1:$H$59,MATCH(I$1,$B$1:$H$1,0),0) -> #N/A | J11: =VLOOKUP($A11,$B$1:$H$59,MATCH(J$1,$B$1:$H$1,0),0) -> #N/A | K11: =VLOOKUP($A11,$B$1:$H$59,MATCH(K$1,$B$1:$H$1,0),0) -> #N/A | L11: =VLOOKUP($A11,$B$1:$H$59,MATCH(L$1,$B$1:$H$1,0),0) -> #N/A | M11: =VLOOKUP($A11,$B$1:$H$59,MATCH(M$1,$B$1:$H$1,0),0) -> #N/A | N11: =VLOOKUP($A11,$B$1:$H$59,MATCH(N$1,$B$1:$H$1,0),0) -> #N/A | P11: =B11 -> 43917 | Q11: =VLOOKUP($B11,'Stats 2020'!$D$25:$J$200,MATCH(Graphs!Q$1,'Stats 2020'!$D$18:$J$18,0),0) -> 1 | R11: =VLOOKUP($B11,'Stats 2020'!$D$25:$J$200,MATCH(Graphs!R$1,'Stats 2020'!$D$18:$J$18,0),0) -> 1 | S11: =VLOOKUP($B11,'Stats 2020'!$D$25:$J$200,MATCH(Graphs!S$1,'Stats 2020'!$D$18:$J$18,0),0) -> 1 | T11: =VLOOKUP($B11,'Stats 2020'!$D$25:$J$200,MATCH(Graphs!T$1,'Stats 2020'!$D$18:$J$18,0),0) -> 1 | U11: =VLOOKUP($B11,'Stats 2020'!$D$25:$J$200,MATCH(Graphs!U$1,'Stats 2020'!$D$18:$J$18,0),0) -> 1 | V11: =VLOOKUP($B11,'Stats 2020'!$D$25:$J$200,MATCH(Graphs!V$1,'Stats 2020'!$D$18:$J$18,0),0) -> 1 | X11: =B11 -> 43917 | Y11: =SUM(Q$2:Q11)/COUNTA($P$2:$P11) -> 0.9 | Z11: =SUM(R$2:R11)/COUNTA($P$2:$P11) -> 0.1 | AA11: =SUM(S$2:S11)/COUNTA($P$2:$P11) -> 0.8 | AB11: =SUM(T$2:T11)/COUNTA($P$2:$P11) -> 0.2 | AC11: =SUM(U$2:U11)/COUNTA($P$2:$P11) -> 0.7 | AD11: =SUM(V$2:V11)/COUNTA($P$2:$P11) -> 0.9 | AE11: =AVERAGE(Y11:AD11) -> 0.6 | AF11: =VLOOKUP($A11,$X$1:$AE$59,MATCH(AF$1,$X$1:$AE$1,0),0) -> #N/A | AG11: =VLOOKUP($A11,$X$1:$AE$59,MATCH(AG$1,$X$1:$AE$1,0),0) -> #N/A | AH11: =VLOOKUP($A11,$X$1:$AE$59,MATCH(AH$1,$X$1:$AE$1,0),0) -> #N/A | AI11: =VLOOKUP($A11,$X$1:$AE$59,MATCH(AI$1,$X$1:$AE$1,0),0) -> #N/A | AJ11: =VLOOKUP($A11,$X$1:$AE$59,MATCH(AJ$1,$X$1:$AE$1,0),0) -> #N/A | AK11: =VLOOKUP($A11,$X$1:$AE$59,MATCH(AK$1,$X$1:$AE$1,0),0) -> #N/A | AL11: =VLOOKUP($A11,$X$1:$AE$59,MATCH(AL$1,$X$1:$AE$1,0),0) -> #N/A
A12: =IF(AND((TODAY()-B12)<7,(TODAY()-B12>=0)),B12,NA()) -> #N/A | B12: =B10+14 -> 43924 | C12: =IF($B12<=TODAY(),SUMIF('Stats 2020'!$M$24:$M$1048576,"<="&Graphs!$B12,'Stats 2020'!O$24:O$1048576),NA()) -> 63.75 | D12: =IF($B12<=TODAY(),MAX($C12,$E12,$G12,$H12)+11+16.5,NA()) -> 113.25 | E12: =IF($B12<=TODAY(),SUMIF('Stats 2020'!$M$24:$M$1048576,"<="&Graphs!$B12,'Stats 2020'!Q$24:Q$1048576),NA()) -> 72 | F12: =IF($B12<=TODAY(),MAX($C12,$E12,$G12,$H12)+11+16.5,NA()) -> 113.25 | G12: =IF($B12<=TODAY(),SUMIF('Stats 2020'!$M$24:$M$1048576,"<="&Graphs!$B12,'Stats 2020'!S$24:S$1048576),NA()) -> 85.75 | H12: =IF($B12<=TODAY(),SUMIF('Stats 2020'!$M$24:$M$1048576,"<="&Graphs!$B12,'Stats 2020'!T$24:T$1048576),NA()) -> 61 | I12: =VLOOKUP($A12,$B$1:$H$59,MATCH(I$1,$B$1:$H$1,0),0) -> #N/A | J12: =VLOOKUP($A12,$B$1:$H$59,MATCH(J$1,$B$1:$H$1,0),0) -> #N/A | K12: =VLOOKUP($A12,$B$1:$H$59,MATCH(K$1,$B$1:$H$1,0),0) -> #N/A | L12: =VLOOKUP($A12,$B$1:$H$59,MATCH(L$1,$B$1:$H$1,0),0) -> #N/A | M12: =VLOOKUP($A12,$B$1:$H$59,MATCH(M$1,$B$1:$H$1,0),0) -> #N/A | N12: =VLOOKUP($A12,$B$1:$H$59,MATCH(N$1,$B$1:$H$1,0),0) -> #N/A | P12: =B12 -> 43924 | Q12: =VLOOKUP($B12,'Stats 2020'!$D$25:$J$200,MATCH(Graphs!Q$1,'Stats 2020'!$D$18:$J$18,0),0) -> 1 | R12: =VLOOKUP($B12,'Stats 2020'!$D$25:$J$200,MATCH(Graphs!R$1,'Stats 2020'!$D$18:$J$18,0),0) | S12: =VLOOKUP($B12,'Stats 2020'!$D$25:$J$200,MATCH(Graphs!S$1,'Stats 2020'!$D$18:$J$18,0),0) -> 1 | T12: =VLOOKUP($B12,'Stats 2020'!$D$25:$J$200,MATCH(Graphs!T$1,'Stats 2020'!$D$18:$J$18,0),0) -> 1 | U12: =VLOOKUP($B12,'Stats 2020'!$D$25:$J$200,MATCH(Graphs!U$1,'Stats 2020'!$D$18:$J$18,0),0) -> 1 | V12: =VLOOKUP($B12,'Stats 2020'!$D$25:$J$200,MATCH(Graphs!V$1,'Stats 2020'!$D$18:$J$18,0),0) -> 1 | X12: =B12 -> 43924 | Y12: =SUM(Q$2:Q12)/COUNTA($P$2:$P12) -> 0.90909091 | Z12: =SUM(R$2:R12)/COUNTA($P$2:$P12) -> 0.090909091 | AA12: =SUM(S$2:S12)/COUNTA($P$2:$P12) -> 0.81818182 | AB12: =SUM(T$2:T12)/COUNTA($P$2:$P12) -> 0.27272727 | AC12: =SUM(U$2:U12)/COUNTA($P$2:$P12) -> 0.72727273 | AD12: =SUM(V$2:V12)/COUNTA($P$2:$P12) -> 0.90909091 | AE12: =AVERAGE(Y12:AD12) -> 0.62121212 | AF12: =VLOOKUP($A12,$X$1:$AE$59,MATCH(AF$1,$X$1:$AE$1,0),0) -> #N/A | AG12: =VLOOKUP($A12,$X$1:$AE$59,MATCH(AG$1,$X$1:$AE$1,0),0) -> #N/A | AH12: =VLOOKUP($A12,$X$1:$AE$59,MATCH(AH$1,$X$1:$AE$1,0),0) -> #N/A | AI12: =VLOOKUP($A12,$X$1:$AE$59,MATCH(AI$1,$X$1:$AE$1,0),0) -> #N/A | AJ12: =VLOOKUP($A12,$X$1:$AE$59,MATCH(AJ$1,$X$1:$AE$1,0),0) -> #N/A | AK12: =VLOOKUP($A12,$X$1:$AE$59,MATCH(AK$1,$X$1:$AE$1,0),0) -> #N/A | AL12: =VLOOKUP($A12,$X$1:$AE$59,MATCH(AL$1,$X$1:$AE$1,0),0) -> #N/A
A13: =IF(AND((TODAY()-B13)<7,(TODAY()-B13>=0)),B13,NA()) -> #N/A | B13: =B12+7 -> 43931 | C13: =IF($B13<=TODAY(),SUMIF('Stats 2020'!$M$24:$M$1048576,"<="&Graphs!$B13,'Stats 2020'!O$24:O$1048576),NA()) -> 63.75 | D13: =IF($B13<=TODAY(),MAX($C13,$E13,$G13,$H13)+11+16.5,NA()) -> 113.25 | E13: =IF($B13<=TODAY(),SUMIF('Stats 2020'!$M$24:$M$1048576,"<="&Graphs!$B13,'Stats 2020'!Q$24:Q$1048576),NA()) -> 72 | F13: =IF($B13<=TODAY(),MAX($C13,$E13,$G13,$H13)+11+16.5,NA()) -> 113.25 | G13: =IF($B13<=TODAY(),SUMIF('Stats 2020'!$M$24:$M$1048576,"<="&Graphs!$B13,'Stats 2020'!S$24:S$1048576),NA()) -> 85.75 | H13: =IF($B13<=TODAY(),SUMIF('Stats 2020'!$M$24:$M$1048576,"<="&Graphs!$B13,'Stats 2020'!T$24:T$1048576),NA()) -> 61 | I13: =VLOOKUP($A13,$B$1:$H$59,MATCH(I$1,$B$1:$H$1,0),0) -> #N/A | J13: =VLOOKUP($A13,$B$1:$H$59,MATCH(J$1,$B$1:$H$1,0),0) -> #N/A | K13: =VLOOKUP($A13,$B$1:$H$59,MATCH(K$1,$B$1:$H$1,0),0) -> #N/A | L13: =VLOOKUP($A13,$B$1:$H$59,MATCH(L$1,$B$1:$H$1,0),0) -> #N/A | M13: =VLOOKUP($A13,$B$1:$H$59,MATCH(M$1,$B$1:$H$1,0),0) -> #N/A | N13: =VLOOKUP($A13,$B$1:$H$59,MATCH(N$1,$B$1:$H$1,0),0) -> #N/A | P13: =B13 -> 43931 | X13: =B13 -> 43931 | Y13: =SUM(Q$2:Q12)/COUNTA($P$2:$P12) -> 0.90909091 | Z13: =SUM(R$2:R12)/COUNTA($P$2:$P12) -> 0.090909091 | AA13: =SUM(S$2:S12)/COUNTA($P$2:$P12) -> 0.81818182 | AB13: =SUM(T$2:T12)/COUNTA($P$2:$P12) -> 0.27272727 | AC13: =SUM(U$2:U12)/COUNTA($P$2:$P12) -> 0.72727273 | AD13: =SUM(V$2:V12)/COUNTA($P$2:$P12) -> 0.90909091 | AE13: =AVERAGE(Y13:AD13) -> 0.62121212 | AF13: =VLOOKUP($A13,$X$1:$AE$59,MATCH(AF$1,$X$1:$AE$1,0),0) -> #N/A | AG13: =VLOOKUP($A13,$X$1:$AE$59,MATCH(AG$1,$X$1:$AE$1,0),0) -> #N/A | AH13: =VLOOKUP($A13,$X$1:$AE$59,MATCH(AH$1,$X$1:$AE$1,0),0) -> #N/A | AI13: =VLOOKUP($A13,$X$1:$AE$59,MATCH(AI$1,$X$1:$AE$1,0),0) -> #N/A | AJ13: =VLOOKUP($A13,$X$1:$AE$59,MATCH(AJ$1,$X$1:$AE$1,0),0) -> #N/A | AK13: =VLOOKUP($A13,$X$1:$AE$59,MATCH(AK$1,$X$1:$AE$1,0),0) -> #N/A | AL13: =VLOOKUP($A13,$X$1:$AE$59,MATCH(AL$1,$X$1:$AE$1,0),0) -> #N/A
A14: =IF(AND((TODAY()-B14)<7,(TODAY()-B14>=0)),B14,NA()) -> #N/A | B14: =B13+7 -> 43938 | C14: =IF($B14<=TODAY(),SUMIF('Stats 2020'!$M$24:$M$1048576,"<="&Graphs!$B14,'Stats 2020'!O$24:O$1048576),NA()) -> 74.75 | D14: =IF($B14<=TODAY(),MAX($C14,$E14,$G14,$H14)+11+16.5,NA()) -> 113.25 | E14: =IF($B14<=TODAY(),SUMIF('Stats 2020'!$M$24:$M$1048576,"<="&Graphs!$B14,'Stats 2020'!Q$24:Q$1048576),NA()) -> 72 | F14: =IF($B14<=TODAY(),MAX($C14,$E14,$G14,$H14)+11+16.5,NA()) -> 113.25 | G14: =IF($B14<=TODAY(),SUMIF('Stats 2020'!$M$24:$M$1048576,"<="&Graphs!$B14,'Stats 2020'!S$24:S$1048576),NA()) -> 85.75 | H14: =IF($B14<=TODAY(),SUMIF('Stats 2020'!$M$24:$M$1048576,"<="&Graphs!$B14,'Stats 2020'!T$24:T$1048576),NA()) -> 61 | I14: =VLOOKUP($A14,$B$1:$H$59,MATCH(I$1,$B$1:$H$1,0),0) -> #N/A | J14: =VLOOKUP($A14,$B$1:$H$59,MATCH(J$1,$B$1:$H$1,0),0) -> #N/A | K14: =VLOOKUP($A14,$B$1:$H$59,MATCH(K$1,$B$1:$H$1,0),0) -> #N/A | L14: =VLOOKUP($A14,$B$1:$H$59,MATCH(L$1,$B$1:$H$1,0),0) -> #N/A | M14: =VLOOKUP($A14,$B$1:$H$59,MATCH(M$1,$B$1:$H$1,0),0) -> #N/A | N14: =VLOOKUP($A14,$B$1:$H$59,MATCH(N$1,$B$1:$H$1,0),0) -> #N/A | P14: =B14 -> 43938 | Q14: =VLOOKUP($B14,'Stats 2020'!$D$25:$J$200,MATCH(Graphs!Q$1,'Stats 2020'!$D$18:$J$18,0),0) -> 1 | R14: =VLOOKUP($B14,'Stats 2020'!$D$25:$J$200,MATCH(Graphs!R$1,'Stats 2020'!$D$18:$J$18,0),0) | S14: =VLOOKUP($B14,'Stats 2020'!$D$25:$J$200,MATCH(Graphs!S$1,'Stats 2020'!$D$18:$J$18,0),0) -> 1 | T14: =VLOOKUP($B14,'Stats 2020'!$D$25:$J$200,MATCH(Graphs!T$1,'Stats 2020'!$D$18:$J$18,0),0) | U14: =VLOOKUP($B14,'Stats 2020'!$D$25:$J$200,MATCH(Graphs!U$1,'Stats 2020'!$D$18:$J$18,0),0) -> 1 | V14: =VLOOKUP($B14,'Stats 2020'!$D$25:$J$200,MATCH(Graphs!V$1,'Stats 2020'!$D$18:$J$18,0),0) -> 1 | X14: =B14 -> 43938 | Y14: =SUM(Q$2:Q14)/COUNTA($P$2:$P14) -> 0.84615385 | Z14: =SUM(R$2:R14)/COUNTA($P$2:$P14) -> 0.076923077 | AA14: =SUM(S$2:S14)/COUNTA($P$2:$P14) -> 0.76923077 | AB14: =SUM(T$2:T14)/COUNTA($P$2:$P14) -> 0.23076923 | AC14: =SUM(U$2:U14)/COUNTA($P$2:$P14) -> 0.69230769 | AD14: =SUM(V$2:V14)/COUNTA($P$2:$P14) -> 0.84615385 | AE14: =AVERAGE(Y14:AD14) -> 0.57692308 | AF14: =VLOOKUP($A14,$X$1:$AE$59,MATCH(AF$1,$X$1:$AE$1,0),0) -> #N/A | AG14: =VLOOKUP($A14,$X$1:$AE$59,MATCH(AG$1,$X$1:$AE$1,0),0) -> #N/A | AH14: =VLOOKUP($A14,$X$1:$AE$59,MATCH(AH$1,$X$1:$AE$1,0),0) -> #N/A | AI14: =VLOOKUP($A14,$X$1:$AE$59,MATCH(AI$1,$X$1:$AE$1,0),0) -> #N/A | AJ14: =VLOOKUP($A14,$X$1:$AE$59,MATCH(AJ$1,$X$1:$AE$1,0),0) -> #N/A | AK14: =VLOOKUP($A14,$X$1:$AE$59,MATCH(AK$1,$X$1:$AE$1,0),0) -> #N/A | AL14: =VLOOKUP($A14,$X$1:$AE$59,MATCH(AL$1,$X$1:$AE$1,0),0) -> #N/A
A15: =IF(AND((TODAY()-B15)<7,(TODAY()-B15>=0)),B15,NA()) -> #N/A | B15: =B14+7 -> 43945 | C15: =IF($B15<=TODAY(),SUMIF('Stats 2020'!$M$24:$M$1048576,"<="&Graphs!$B15,'Stats 2020'!O$24:O$1048576),NA()) -> 74.75 | D15: =IF($B15<=TODAY(),MAX($C15,$E15,$G15,$H15)+11+16.5,NA()) -> 113.25 | E15: =IF($B15<=TODAY(),SUMIF('Stats 2020'!$M$24:$M$1048576,"<="&Graphs!$B15,'Stats 2020'!Q$24:Q$1048576),NA()) -> 72 | F15: =IF($B15<=TODAY(),MAX($C15,$E15,$G15,$H15)+11+16.5,NA()) -> 113.25 | G15: =IF($B15<=TODAY(),SUMIF('Stats 2020'!$M$24:$M$1048576,"<="&Graphs!$B15,'Stats 2020'!S$24:S$1048576),NA()) -> 85.75 | H15: =IF($B15<=TODAY(),SUMIF('Stats 2020'!$M$24:$M$1048576,"<="&Graphs!$B15,'Stats 2020'!T$24:T$1048576),NA()) -> 61 | I15: =VLOOKUP($A15,$B$1:$H$59,MATCH(I$1,$B$1:$H$1,0),0) -> #N/A | J15: =VLOOKUP($A15,$B$1:$H$59,MATCH(J$1,$B$1:$H$1,0),0) -> #N/A | K15: =VLOOKUP($A15,$B$1:$H$59,MATCH(K$1,$B$1:$H$1,0),0) -> #N/A | L15: =VLOOKUP($A15,$B$1:$H$59,MATCH(L$1,$B$1:$H$1,0),0) -> #N/A | M15: =VLOOKUP($A15,$B$1:$H$59,MATCH(M$1,$B$1:$H$1,0),0) -> #N/A | N15: =VLOOKUP($A15,$B$1:$H$59,MATCH(N$1,$B$1:$H$1,0),0) -> #N/A | P15: =B15 -> 43945 | Q15: =VLOOKUP($B15,'Stats 2020'!$D$25:$J$200,MATCH(Graphs!Q$1,'Stats 2020'!$D$18:$J$18,0),0) -> 1 | R15: =VLOOKUP($B15,'Stats 2020'!$D$25:$J$200,MATCH(Graphs!R$1,'Stats 2020'!$D$18:$J$18,0),0) | S15: =VLOOKUP($B15,'Stats 2020'!$D$25:$J$200,MATCH(Graphs!S$1,'Stats 2020'!$D$18:$J$18,0),0) -> 1 | T15: =VLOOKUP($B15,'Stats 2020'!$D$25:$J$200,MATCH(Graphs!T$1,'Stats 2020'!$D$18:$J$18,0),0) -> 1 | U15: =VLOOKUP($B15,'Stats 2020'!$D$25:$J$200,MATCH(Graphs!U$1,'Stats 2020'!$D$18:$J$18,0),0) -> 1 | V15: =VLOOKUP($B15,'Stats 2020'!$D$25:$J$200,MATCH(Graphs!V$1,'Stats 2020'!$D$18:$J$18,0),0) -> 1 | X15: =B15 -> 43945 | Y15: =SUM(Q$2:Q15)/COUNTA($P$2:$P15) -> 0.85714286 | Z15: =SUM(R$2:R15)/COUNTA($P$2:$P15) -> 0.071428571 | AA15: =SUM(S$2:S15)/COUNTA($P$2:$P15) -> 0.78571429 | AB15: =SUM(T$2:T15)/COUNTA($P$2:$P15) -> 0.28571429 | AC15: =SUM(U$2:U15)/COUNTA($P$2:$P15) -> 0.71428571 | AD15: =SUM(V$2:V15)/COUNTA($P$2:$P15) -> 0.85714286 | AE15: =AVERAGE(Y15:AD15) -> 0.5952381 | AF15: =VLOOKUP($A15,$X$1:$AE$59,MATCH(AF$1,$X$1:$AE$1,0),0) -> #N/A | AG15: =VLOOKUP($A15,$X$1:$AE$59,MATCH(AG$1,$X$1:$AE$1,0),0) -> #N/A | AH15: =VLOOKUP($A15,$X$1:$AE$59,MATCH(AH$1,$X$1:$AE$1,0),0) -> #N/A | AI15: =VLOOKUP($A15,$X$1:$AE$59,MATCH(AI$1,$X$1:$AE$1,0),0) -> #N/A | AJ15: =VLOOKUP($A15,$X$1:$AE$59,MATCH(AJ$1,$X$1:$AE$1,0),0) -> #N/A | AK15: =VLOOKUP($A15,$X$1:$AE$59,MATCH(AK$1,$X$1:$AE$1,0),0) -> #N/A | AL15: =VLOOKUP($A15,$X$1:$AE$59,MATCH(AL$1,$X$1:$AE$1,0),0) -> #N/A
A16: =IF(AND((TODAY()-B16)<7,(TODAY()-B16>=0)),B16,NA()) -> #N/A | B16: =B15+7 -> 43952 | C16: =IF($B16<=TODAY(),SUMIF('Stats 2020'!$M$24:$M$1048576,"<="&Graphs!$B16,'Stats 2020'!O$24:O$1048576),NA()) -> 74.75 | D16: =IF($B16<=TODAY(),MAX($C16,$E16,$G16,$H16)+11+16.5,NA()) -> 113.25 | E16: =IF($B16<=TODAY(),SUMIF('Stats 2020'!$M$24:$M$1048576,"<="&Graphs!$B16,'Stats 2020'!Q$24:Q$1048576),NA()) -> 72 | F16: =IF($B16<=TODAY(),MAX($C16,$E16,$G16,$H16)+11+16.5,NA()) -> 113.25 | G16: =IF($B16<=TODAY(),SUMIF('Stats 2020'!$M$24:$M$1048576,"<="&Graphs!$B16,'Stats 2020'!S$24:S$1048576),NA()) -> 85.75 | H16: =IF($B16<=TODAY(),SUMIF('Stats 2020'!$M$24:$M$1048576,"<="&Graphs!$B16,'Stats 2020'!T$24:T$1048576),NA()) -> 61 | I16: =VLOOKUP($A16,$B$1:$H$59,MATCH(I$1,$B$1:$H$1,0),0) -> #N/A | J16: =VLOOKUP($A16,$B$1:$H$59,MATCH(J$1,$B$1:$H$1,0),0) -> #N/A | K16: =VLOOKUP($A16,$B$1:$H$59,MATCH(K$1,$B$1:$H$1,0),0) -> #N/A | L16: =VLOOKUP($A16,$B$1:$H$59,MATCH(L$1,$B$1:$H$1,0),0) -> #N/A | M16: =VLOOKUP($A16,$B$1:$H$59,MATCH(M$1,$B$1:$H$1,0),0) -> #N/A | N16: =VLOOKUP($A16,$B$1:$H$59,MATCH(N$1,$B$1:$H$1,0),0) -> #N/A | P16: =B16 -> 43952 | Q16: =VLOOKUP($B16,'Stats 2020'!$D$25:$J$200,MATCH(Graphs!Q$1,'Stats 2020'!$D$18:$J$18,0),0) -> 1 | R16: =VLOOKUP($B16,'Stats 2020'!$D$25:$J$200,MATCH(Graphs!R$1,'Stats 2020'!$D$18:$J$18,0),0) | S16: =VLOOKUP($B16,'Stats 2020'!$D$25:$J$200,MATCH(Graphs!S$1,'Stats 2020'!$D$18:$J$18,0),0) -> 1 | T16: =VLOOKUP($B16,'Stats 2020'!$D$25:$J$200,MATCH(Graphs!T$1,'Stats 2020'!$D$18:$J$18,0),0) -> 1 | U16: =VLOOKUP($B16,'Stats 2020'!$D$25:$J$200,MATCH(Graphs!U$1,'Stats 2020'!$D$18:$J$18,0),0) -> 1 | V16: =VLOOKUP($B16,'Stats 2020'!$D$25:$J$200,MATCH(Graphs!V$1,'Stats 2020'!$D$18:$J$18,0),0) -> 1 | X16: =B16 -> 43952 | Y16: =SUM(Q$2:Q16)/COUNTA($P$2:$P16) -> 0.86666667 | Z16: =SUM(R$2:R16)/COUNTA($P$2:$P16) -> 0.066666667 | AA16: =SUM(S$2:S16)/COUNTA($P$2:$P16) -> 0.8 | AB16: =SUM(T$2:T16)/COUNTA($P$2:$P16) -> 0.33333333 | AC16: =SUM(U$2:U16)/COUNTA($P$2:$P16) -> 0.73333333 | AD16: =SUM(V$2:V16)/COUNTA($P$2:$P16) -> 0.86666667 | AE16: =AVERAGE(Y16:AD16) -> 0.61111111 | AF16: =VLOOKUP($A16,$X$1:$AE$59,MATCH(AF$1,$X$1:$AE$1,0),0) -> #N/A | AG16: =VLOOKUP($A16,$X$1:$AE$59,MATCH(AG$1,$X$1:$AE$1,0),0) -> #N/A | AH16: =VLOOKUP($A16,$X$1:$AE$59,MATCH(AH$1,$X$1:$AE$1,0),0) -> #N/A | AI16: =VLOOKUP($A16,$X$1:$AE$59,MATCH(AI$1,$X$1:$AE$1,0),0) -> #N/A | AJ16: =VLOOKUP($A16,$X$1:$AE$59,MATCH(AJ$1,$X$1:$AE$1,0),0) -> #N/A | AK16: =VLOOKUP($A16,$X$1:$AE$59,MATCH(AK$1,$X$1:$AE$1,0),0) -> #N/A | AL16: =VLOOKUP($A16,$X$1:$AE$59,MATCH(AL$1,$X$1:$AE$1,0),0) -> #N/A
A17: =IF(AND((TODAY()-B17)<7,(TODAY()-B17>=0)),B17,NA()) -> #N/A | B17: =B16+7 -> 43959 | C17: =IF($B17<=TODAY(),SUMIF('Stats 2020'!$M$24:$M$1048576,"<="&Graphs!$B17,'Stats 2020'!O$24:O$1048576),NA()) -> 74.75 | D17: =IF($B17<=TODAY(),MAX($C17,$E17,$G17,$H17)+11+16.5,NA()) -> 113.25 | E17: =IF($B17<=TODAY(),SUMIF('Stats 2020'!$M$24:$M$1048576,"<="&Graphs!$B17,'Stats 2020'!Q$24:Q$1048576),NA()) -> 72 | F17: =IF($B17<=TODAY(),MAX($C17,$E17,$G17,$H17)+11+16.5,NA()) -> 113.25 | G17: =IF($B17<=TODAY(),SUMIF('Stats 2020'!$M$24:$M$1048576,"<="&Graphs!$B17,'Stats 2020'!S$24:S$1048576),NA()) -> 85.75 | H17: =IF($B17<=TODAY(),SUMIF('Stats 2020'!$M$24:$M$1048576,"<="&Graphs!$B17,'Stats 2020'!T$24:T$1048576),NA()) -> 61 | I17: =VLOOKUP($A17,$B$1:$H$59,MATCH(I$1,$B$1:$H$1,0),0) -> #N/A | J17: =VLOOKUP($A17,$B$1:$H$59,MATCH(J$1,$B$1:$H$1,0),0) -> #N/A | K17: =VLOOKUP($A17,$B$1:$H$59,MATCH(K$1,$B$1:$H$1,0),0) -> #N/A | L17: =VLOOKUP($A17,$B$1:$H$59,MATCH(L$1,$B$1:$H$1,0),0) -> #N/A | M17: =VLOOKUP($A17,$B$1:$H$59,MATCH(M$1,$B$1:$H$1,0),0) -> #N/A | N17: =VLOOKUP($A17,$B$1:$H$59,MATCH(N$1,$B$1:$H$1,0),0) -> #N/A | P17: =B17 -> 43959 | Q17: =VLOOKUP($B17,'Stats 2020'!$D$25:$J$200,MATCH(Graphs!Q$1,'Stats 2020'!$D$18:$J$18,0),0) -> 1 | R17: =VLOOKUP($B17,'Stats 2020'!$D$25:$J$200,MATCH(Graphs!R$1,'Stats 2020'!$D$18:$J$18,0),0) | S17: =VLOOKUP($B17,'Stats 2020'!$D$25:$J$200,MATCH(Graphs!S$1,'Stats 2020'!$D$18:$J$18,0),0) -> 1 | T17: =VLOOKUP($B17,'Stats 2020'!$D$25:$J$200,MATCH(Graphs!T$1,'Stats 2020'!$D$18:$J$18,0),0) | U17: =VLOOKUP($B17,'Stats 2020'!$D$25:$J$200,MATCH(Graphs!U$1,'Stats 2020'!$D$18:$J$18,0),0) -> 1 | V17: =VLOOKUP($B17,'Stats 2020'!$D$25:$J$200,MATCH(Graphs!V$1,'Stats 2020'!$D$18:$J$18,0),0) -> 1 | X17: =B17 -> 43959 | Y17: =SUM(Q$2:Q17)/COUNTA($P$2:$P17) -> 0.875 | Z17: =SUM(R$2:R17)/COUNTA($P$2:$P17) -> 0.0625 | AA17: =SUM(S$2:S17)/COUNTA($P$2:$P17) -> 0.8125 | AB17: =SUM(T$2:T17)/COUNTA($P$2:$P17) -> 0.3125 | AC17: =SUM(U$2:U17)/COUNTA($P$2:$P17) -> 0.75 | AD17: =SUM(V$2:V17)/COUNTA($P$2:$P17) -> 0.875 | AE17: =AVERAGE(Y17:AD17) -> 0.61458333 | AF17: =VLOOKUP($A17,$X$1:$AE$59,MATCH(AF$1,$X$1:$AE$1,0),0) -> #N/A | AG17: =VLOOKUP($A17,$X$1:$AE$59,MATCH(AG$1,$X$1:$AE$1,0),0) -> #N/A | AH17: =VLOOKUP($A17,$X$1:$AE$59,MATCH(AH$1,$X$1:$AE$1,0),0) -> #N/A | AI17: =VLOOKUP($A17,$X$1:$AE$59,MATCH(AI$1,$X$1:$AE$1,0),0) -> #N/A | AJ17: =VLOOKUP($A17,$X$1:$AE$59,MATCH(AJ$1,$X$1:$AE$1,0),0) -> #N/A | AK17: =VLOOKUP($A17,$X$1:$AE$59,MATCH(AK$1,$X$1:$AE$1,0),0) -> #N/A | AL17: =VLOOKUP($A17,$X$1:$AE$59,MATCH(AL$1,$X$1:$AE$1,0),0) -> #N/A
A18: =IF(AND((TODAY()-B18)<7,(TODAY()-B18>=0)),B18,NA()) -> #N/A | B18: =B17+7 -> 43966 | C18: =IF($B18<=TODAY(),SUMIF('Stats 2020'!$M$24:$M$1048576,"<="&Graphs!$B18,'Stats 2020'!O$24:O$1048576),NA()) -> 74.75 | D18: =IF($B18<=TODAY(),MAX($C18,$E18,$G18,$H18)+11+16.5,NA()) -> 113.25 | E18: =IF($B18<=TODAY(),SUMIF('Stats 2020'!$M$24:$M$1048576,"<="&Graphs!$B18,'Stats 2020'!Q$24:Q$1048576),NA()) -> 72 | F18: =IF($B18<=TODAY(),MAX($C18,$E18,$G18,$H18)+11+16.5,NA()) -> 113.25 | G18: =IF($B18<=TODAY(),SUMIF('Stats 2020'!$M$24:$M$1048576,"<="&Graphs!$B18,'Stats 2020'!S$24:S$1048576),NA()) -> 85.75 | H18: =IF($B18<=TODAY(),SUMIF('Stats 2020'!$M$24:$M$1048576,"<="&Graphs!$B18,'Stats 2020'!T$24:T$1048576),NA()) -> 61 | I18: =VLOOKUP($A18,$B$1:$H$59,MATCH(I$1,$B$1:$H$1,0),0) -> #N/A | J18: =VLOOKUP($A18,$B$1:$H$59,MATCH(J$1,$B$1:$H$1,0),0) -> #N/A | K18: =VLOOKUP($A18,$B$1:$H$59,MATCH(K$1,$B$1:$H$1,0),0) -> #N/A | L18: =VLOOKUP($A18,$B$1:$H$59,MATCH(L$1,$B$1:$H$1,0),0) -> #N/A | M18: =VLOOKUP($A18,$B$1:$H$59,MATCH(M$1,$B$1:$H$1,0),0) -> #N/A | N18: =VLOOKUP($A18,$B$1:$H$59,MATCH(N$1,$B$1:$H$1,0),0) -> #N/A | P18: =B18 -> 43966 | Q18: =VLOOKUP($B18,'Stats 2020'!$D$25:$J$200,MATCH(Graphs!Q$1,'Stats 2020'!$D$18:$J$18,0),0) -> 1 | R18: =VLOOKUP($B18,'Stats 2020'!$D$25:$J$200,MATCH(Graphs!R$1,'Stats 2020'!$D$18:$J$18,0),0) | S18: =VLOOKUP($B18,'Stats 2020'!$D$25:$J$200,MATCH(Graphs!S$1,'Stats 2020'!$D$18:$J$18,0),0) -> 1 | T18: =VLOOKUP($B18,'Stats 2020'!$D$25:$J$200,MATCH(Graphs!T$1,'Stats 2020'!$D$18:$J$18,0),0) | U18: =VLOOKUP($B18,'Stats 2020'!$D$25:$J$200,MATCH(Graphs!U$1,'Stats 2020'!$D$18:$J$18,0),0) -> 1 | V18: =VLOOKUP($B18,'Stats 2020'!$D$25:$J$200,MATCH(Graphs!V$1,'Stats 2020'!$D$18:$J$18,0),0) -> 1 | X18: =B18 -> 43966 | Y18: =SUM(Q$2:Q18)/COUNTA($P$2:$P18) -> 0.88235294 | Z18: =SUM(R$2:R18)/COUNTA($P$2:$P18) -> 0.058823529 | AA18: =SUM(S$2:S18)/COUNTA($P$2:$P18) -> 0.82352941 | AB18: =SUM(T$2:T18)/COUNTA($P$2:$P18) -> 0.29411765 | AC18: =SUM(U$2:U18)/COUNTA($P$2:$P18) -> 0.76470588 | AD18: =SUM(V$2:V18)/COUNTA($P$2:$P18) -> 0.88235294 | AE18: =AVERAGE(Y18:AD18) -> 0.61764706 | AF18: =VLOOKUP($A18,$X$1:$AE$59,MATCH(AF$1,$X$1:$AE$1,0),0) -> #N/A | AG18: =VLOOKUP($A18,$X$1:$AE$59,MATCH(AG$1,$X$1:$AE$1,0),0) -> #N/A | AH18: =VLOOKUP($A18,$X$1:$AE$59,MATCH(AH$1,$X$1:$AE$1,0),0) -> #N/A | AI18: =VLOOKUP($A18,$X$1:$AE$59,MATCH(AI$1,$X$1:$AE$1,0),0) -> #N/A | AJ18: =VLOOKUP($A18,$X$1:$AE$59,MATCH(AJ$1,$X$1:$AE$1,0),0) -> #N/A | AK18: =VLOOKUP($A18,$X$1:$AE$59,MATCH(AK$1,$X$1:$AE$1,0),0) -> #N/A | AL18: =VLOOKUP($A18,$X$1:$AE$59,MATCH(AL$1,$X$1:$AE$1,0),0) -> #N/A
A19: =IF(AND((TODAY()-B19)<7,(TODAY()-B19>=0)),B19,NA()) -> #N/A | B19: =B18+7 -> 43973 | C19: =IF($B19<=TODAY(),SUMIF('Stats 2020'!$M$24:$M$1048576,"<="&Graphs!$B19,'Stats 2020'!O$24:O$1048576),NA()) -> 74.75 | D19: =IF($B19<=TODAY(),MAX($C19,$E19,$G19,$H19)+11+16.5,NA()) -> 113.25 | E19: =IF($B19<=TODAY(),SUMIF('Stats 2020'!$M$24:$M$1048576,"<="&Graphs!$B19,'Stats 2020'!Q$24:Q$1048576),NA()) -> 72 | F19: =IF($B19<=TODAY(),MAX($C19,$E19,$G19,$H19)+11+16.5,NA()) -> 113.25 | G19: =IF($B19<=TODAY(),SUMIF('Stats 2020'!$M$24:$M$1048576,"<="&Graphs!$B19,'Stats 2020'!S$24:S$1048576),NA()) -> 85.75 | H19: =IF($B19<=TODAY(),SUMIF('Stats 2020'!$M$24:$M$1048576,"<="&Graphs!$B19,'Stats 2020'!T$24:T$1048576),NA()) -> 72 | I19: =VLOOKUP($A19,$B$1:$H$59,MATCH(I$1,$B$1:$H$1,0),0) -> #N/A | J19: =VLOOKUP($A19,$B$1:$H$59,MATCH(J$1,$B$1:$H$1,0),0) -> #N/A | K19: =VLOOKUP($A19,$B$1:$H$59,MATCH(K$1,$B$1:$H$1,0),0) -> #N/A | L19: =VLOOKUP($A19,$B$1:$H$59,MATCH(L$1,$B$1:$H$1,0),0) -> #N/A | M19: =VLOOKUP($A19,$B$1:$H$59,MATCH(M$1,$B$1:$H$1,0),0) -> #N/A | N19: =VLOOKUP($A19,$B$1:$H$59,MATCH(N$1,$B$1:$H$1,0),0) -> #N/A | P19: =B19 -> 43973 | Q19: =VLOOKUP($B19,'Stats 2020'!$D$25:$J$200,MATCH(Graphs!Q$1,'Stats 2020'!$D$18:$J$18,0),0) -> 1 | R19: =VLOOKUP($B19,'Stats 2020'!$D$25:$J$200,MATCH(Graphs!R$1,'Stats 2020'!$D$18:$J$18,0),0) | S19: =VLOOKUP($B19,'Stats 2020'!$D$25:$J$200,MATCH(Graphs!S$1,'Stats 2020'!$D$18:$J$18,0),0) -> 1 | T19: =VLOOKUP($B19,'Stats 2020'!$D$25:$J$200,MATCH(Graphs!T$1,'Stats 2020'!$D$18:$J$18,0),0) | U19: =VLOOKUP($B19,'Stats 2020'!$D$25:$J$200,MATCH(Graphs!U$1,'Stats 2020'!$D$18:$J$18,0),0) -> 1 | V19: =VLOOKUP($B19,'Stats 2020'!$D$25:$J$200,MATCH(Graphs!V$1,'Stats 2020'!$D$18:$J$18,0),0) -> 0 | X19: =B19 -> 43973 | Y19: =SUM(Q$2:Q19)/COUNTA($P$2:$P19) -> 0.88888889 | Z19: =SUM(R$2:R19)/COUNTA($P$2:$P19) -> 0.055555556 | AA19: =SUM(S$2:S19)/COUNTA($P$2:$P19) -> 0.83333333 | AB19: =SUM(T$2:T19)/COUNTA($P$2:$P19) -> 0.27777778 | AC19: =SUM(U$2:U19)/COUNTA($P$2:$P19) -> 0.77777778 | AD19: =SUM(V$2:V19)/COUNTA($P$2:$P19) -> 0.83333333 | AE19: =AVERAGE(Y19:AD19) -> 0.61111111 | AF19: =VLOOKUP($A19,$X$1:$AE$59,MATCH(AF$1,$X$1:$AE$1,0),0) -> #N/A | AG19: =VLOOKUP($A19,$X$1:$AE$59,MATCH(AG$1,$X$1:$AE$1,0),0) -> #N/A | AH19: =VLOOKUP($A19,$X$1:$AE$59,MATCH(AH$1,$X$1:$AE$1,0),0) -> #N/A | AI19: =VLOOKUP($A19,$X$1:$AE$59,MATCH(AI$1,$X$1:$AE$1,0),0) -> #N/A | AJ19: =VLOOKUP($A19,$X$1:$AE$59,MATCH(AJ$1,$X$1:$AE$1,0),0) -> #N/A | AK19: =VLOOKUP($A19,$X$1:$AE$59,MATCH(AK$1,$X$1:$AE$1,0),0) -> #N/A | AL19: =VLOOKUP($A19,$X$1:$AE$59,MATCH(AL$1,$X$1:$AE$1,0),0) -> #N/A
A20: =IF(AND((TODAY()-B20)<7,(TODAY()-B20>=0)),B20,NA()) -> #N/A | B20: =B19+7 -> 43980 | C20: =IF($B20<=TODAY(),SUMIF('Stats 2020'!$M$24:$M$1048576,"<="&Graphs!$B20,'Stats 2020'!O$24:O$1048576),NA()) -> 77.5 | D20: =IF($B20<=TODAY(),MAX($C20,$E20,$G20,$H20)+11+16.5,NA()) -> 113.25 | E20: =IF($B20<=TODAY(),SUMIF('Stats 2020'!$M$24:$M$1048576,"<="&Graphs!$B20,'Stats 2020'!Q$24:Q$1048576),NA()) -> 72 | F20: =IF($B20<=TODAY(),MAX($C20,$E20,$G20,$H20)+11+16.5,NA()) -> 113.25 | G20: =IF($B20<=TODAY(),SUMIF('Stats 2020'!$M$24:$M$1048576,"<="&Graphs!$B20,'Stats 2020'!S$24:S$1048576),NA()) -> 85.75 | H20: =IF($B20<=TODAY(),SUMIF('Stats 2020'!$M$24:$M$1048576,"<="&Graphs!$B20,'Stats 2020'!T$24:T$1048576),NA()) -> 72 | I20: =VLOOKUP($A20,$B$1:$H$59,MATCH(I$1,$B$1:$H$1,0),0) -> #N/A | J20: =VLOOKUP($A20,$B$1:$H$59,MATCH(J$1,$B$1:$H$1,0),0) -> #N/A | K20: =VLOOKUP($A20,$B$1:$H$59,MATCH(K$1,$B$1:$H$1,0),0) -> #N/A | L20: =VLOOKUP($A20,$B$1:$H$59,MATCH(L$1,$B$1:$H$1,0),0) -> #N/A | M20: =VLOOKUP($A20,$B$1:$H$59,MATCH(M$1,$B$1:$H$1,0),0) -> #N/A | N20: =VLOOKUP($A20,$B$1:$H$59,MATCH(N$1,$B$1:$H$1,0),0) -> #N/A | P20: =B20 -> 43980 | Q20: =VLOOKUP($B20,'Stats 2020'!$D$25:$J$200,MATCH(Graphs!Q$1,'Stats 2020'!$D$18:$J$18,0),0) -> 1 | R20: =VLOOKUP($B20,'Stats 2020'!$D$25:$J$200,MATCH(Graphs!R$1,'Stats 2020'!$D$18:$J$18,0),0) | S20: =VLOOKUP($B20,'Stats 2020'!$D$25:$J$200,MATCH(Graphs!S$1,'Stats 2020'!$D$18:$J$18,0),0) -> 1 | T20: =VLOOKUP($B20,'Stats 2020'!$D$25:$J$200,MATCH(Graphs!T$1,'Stats 2020'!$D$18:$J$18,0),0) | U20: =VLOOKUP($B20,'Stats 2020'!$D$25:$J$200,MATCH(Graphs!U$1,'Stats 2020'!$D$18:$J$18,0),0) -> 1 | V20: =VLOOKUP($B20,'Stats 2020'!$D$25:$J$200,MATCH(Graphs!V$1,'Stats 2020'!$D$18:$J$18,0),0) -> 1 | X20: =B20 -> 43980 | Y20: =SUM(Q$2:Q20)/COUNTA($P$2:$P20) -> 0.89473684 | Z20: =SUM(R$2:R20)/COUNTA($P$2:$P20) -> 0.052631579 | AA20: =SUM(S$2:S20)/COUNTA($P$2:$P20) -> 0.84210526 | AB20: =SUM(T$2:T20)/COUNTA($P$2:$P20) -> 0.26315789 | AC20: =SUM(U$2:U20)/COUNTA($P$2:$P20) -> 0.78947368 | AD20: =SUM(V$2:V20)/COUNTA($P$2:$P20) -> 0.84210526 | AE20: =AVERAGE(Y20:AD20) -> 0.61403509 | AF20: =VLOOKUP($A20,$X$1:$AE$59,MATCH(AF$1,$X$1:$AE$1,0),0) -> #N/A | AG20: =VLOOKUP($A20,$X$1:$AE$59,MATCH(AG$1,$X$1:$AE$1,0),0) -> #N/A | AH20: =VLOOKUP($A20,$X$1:$AE$59,MATCH(AH$1,$X$1:$AE$1,0),0) -> #N/A | AI20: =VLOOKUP($A20,$X$1:$AE$59,MATCH(AI$1,$X$1:$AE$1,0),0) -> #N/A | AJ20: =VLOOKUP($A20,$X$1:$AE$59,MATCH(AJ$1,$X$1:$AE$1,0),0) -> #N/A | AK20: =VLOOKUP($A20,$X$1:$AE$59,MATCH(AK$1,$X$1:$AE$1,0),0) -> #N/A | AL20: =VLOOKUP($A20,$X$1:$AE$59,MATCH(AL$1,$X$1:$AE$1,0),0) -> #N/A
A21: =IF(AND((TODAY()-B21)<7,(TODAY()-B21>=0)),B21,NA()) -> #N/A | B21: =B20+7 -> 43987 | C21: =IF($B21<=TODAY(),SUMIF('Stats 2020'!$M$24:$M$1048576,"<="&Graphs!$B21,'Stats 2020'!O$24:O$1048576),NA()) -> 77.5 | D21: =IF($B21<=TODAY(),MAX($C21,$E21,$G21,$H21)+11+16.5,NA()) -> 113.25 | E21: =IF($B21<=TODAY(),SUMIF('Stats 2020'!$M$24:$M$1048576,"<="&Graphs!$B21,'Stats 2020'!Q$24:Q$1048576),NA()) -> 72 | F21: =IF($B21<=TODAY(),MAX($C21,$E21,$G21,$H21)+11+16.5,NA()) -> 113.25 | G21: =IF($B21<=TODAY(),SUMIF('Stats 2020'!$M$24:$M$1048576,"<="&Graphs!$B21,'Stats 2020'!S$24:S$1048576),NA()) -> 85.75 | H21: =IF($B21<=TODAY(),SUMIF('Stats 2020'!$M$24:$M$1048576,"<="&Graphs!$B21,'Stats 2020'!T$24:T$1048576),NA()) -> 72 | I21: =VLOOKUP($A21,$B$1:$H$59,MATCH(I$1,$B$1:$H$1,0),0) -> #N/A | J21: =VLOOKUP($A21,$B$1:$H$59,MATCH(J$1,$B$1:$H$1,0),0) -> #N/A | K21: =VLOOKUP($A21,$B$1:$H$59,MATCH(K$1,$B$1:$H$1,0),0) -> #N/A | L21: =VLOOKUP($A21,$B$1:$H$59,MATCH(L$1,$B$1:$H$1,0),0) -> #N/A | M21: =VLOOKUP($A21,$B$1:$H$59,MATCH(M$1,$B$1:$H$1,0),0) -> #N/A | N21: =VLOOKUP($A21,$B$1:$H$59,MATCH(N$1,$B$1:$H$1,0),0) -> #N/A | P21: =B21 -> 43987 | Q21: =VLOOKUP($B21,'Stats 2020'!$D$25:$J$200,MATCH(Graphs!Q$1,'Stats 2020'!$D$18:$J$18,0),0) -> 1 | R21: =VLOOKUP($B21,'Stats 2020'!$D$25:$J$200,MATCH(Graphs!R$1,'Stats 2020'!$D$18:$J$18,0),0) | S21: =VLOOKUP($B21,'Stats 2020'!$D$25:$J$200,MATCH(Graphs!S$1,'Stats 2020'!$D$18:$J$18,0),0) -> 1 | T21: =VLOOKUP($B21,'Stats 2020'!$D$25:$J$200,MATCH(Graphs!T$1,'Stats 2020'!$D$18:$J$18,0),0) | U21: =VLOOKUP($B21,'Stats 2020'!$D$25:$J$200,MATCH(Graphs!U$1,'Stats 2020'!$D$18:$J$18,0),0) -> 1 | V21: =VLOOKUP($B21,'Stats 2020'!$D$25:$J$200,MATCH(Graphs!V$1,'Stats 2020'!$D$18:$J$18,0),0) -> 1 | X21: =B21 -> 43987 | Y21: =SUM(Q$2:Q21)/COUNTA($P$2:$P21) -> 0.9 | Z21: =SUM(R$2:R21)/COUNTA($P$2:$P21) -> 0.05 | AA21: =SUM(S$2:S21)/COUNTA($P$2:$P21) -> 0.85 | AB21: =SUM(T$2:T21)/COUNTA($P$2:$P21) -> 0.25 | AC21: =SUM(U$2:U21)/COUNTA($P$2:$P21) -> 0.8 | AD21: =SUM(V$2:V21)/COUNTA($P$2:$P21) -> 0.85 | AE21: =AVERAGE(Y21:AD21) -> 0.61666667 | AF21: =VLOOKUP($A21,$X$1:$AE$59,MATCH(AF$1,$X$1:$AE$1,0),0) -> #N/A | AG21: =VLOOKUP($A21,$X$1:$AE$59,MATCH(AG$1,$X$1:$AE$1,0),0) -> #N/A | AH21: =VLOOKUP($A21,$X$1:$AE$59,MATCH(AH$1,$X$1:$AE$1,0),0) -> #N/A | AI21: =VLOOKUP($A21,$X$1:$AE$59,MATCH(AI$1,$X$1:$AE$1,0),0) -> #N/A | AJ21: =VLOOKUP($A21,$X$1:$AE$59,MATCH(AJ$1,$X$1:$AE$1,0),0) -> #N/A | AK21: =VLOOKUP($A21,$X$1:$AE$59,MATCH(AK$1,$X$1:$AE$1,0),0) -> #N/A | AL21: =VLOOKUP($A21,$X$1:$AE$59,MATCH(AL$1,$X$1:$AE$1,0),0) -> #N/A
A22: =IF(AND((TODAY()-B22)<7,(TODAY()-B22>=0)),B22,NA()) -> #N/A | B22: =B21+7 -> 43994 | C22: =IF($B22<=TODAY(),SUMIF('Stats 2020'!$M$24:$M$1048576,"<="&Graphs!$B22,'Stats 2020'!O$24:O$1048576),NA()) -> 77.5 | D22: =IF($B22<=TODAY(),MAX($C22,$E22,$G22,$H22)+11+16.5,NA()) -> 113.25 | E22: =IF($B22<=TODAY(),SUMIF('Stats 2020'!$M$24:$M$1048576,"<="&Graphs!$B22,'Stats 2020'!Q$24:Q$1048576),NA()) -> 72 | F22: =IF($B22<=TODAY(),MAX($C22,$E22,$G22,$H22)+11+16.5,NA()) -> 113.25 | G22: =IF($B22<=TODAY(),SUMIF('Stats 2020'!$M$24:$M$1048576,"<="&Graphs!$B22,'Stats 2020'!S$24:S$1048576),NA()) -> 85.75 | H22: =IF($B22<=TODAY(),SUMIF('Stats 2020'!$M$24:$M$1048576,"<="&Graphs!$B22,'Stats 2020'!T$24:T$1048576),NA()) -> 72 | I22: =VLOOKUP($A22,$B$1:$H$59,MATCH(I$1,$B$1:$H$1,0),0) -> #N/A | J22: =VLOOKUP($A22,$B$1:$H$59,MATCH(J$1,$B$1:$H$1,0),0) -> #N/A | K22: =VLOOKUP($A22,$B$1:$H$59,MATCH(K$1,$B$1:$H$1,0),0) -> #N/A | L22: =VLOOKUP($A22,$B$1:$H$59,MATCH(L$1,$B$1:$H$1,0),0) -> #N/A | M22: =VLOOKUP($A22,$B$1:$H$59,MATCH(M$1,$B$1:$H$1,0),0) -> #N/A | N22: =VLOOKUP($A22,$B$1:$H$59,MATCH(N$1,$B$1:$H$1,0),0) -> #N/A | P22: =B22 -> 43994 | Q22: =VLOOKUP($B22,'Stats 2020'!$D$25:$J$200,MATCH(Graphs!Q$1,'Stats 2020'!$D$18:$J$18,0),0) -> 1 | R22: =VLOOKUP($B22,'Stats 2020'!$D$25:$J$200,MATCH(Graphs!R$1,'Stats 2020'!$D$18:$J$18,0),0) | S22: =VLOOKUP($B22,'Stats 2020'!$D$25:$J$200,MATCH(Graphs!S$1,'Stats 2020'!$D$18:$J$18,0),0) -> 1 | T22: =VLOOKUP($B22,'Stats 2020'!$D$25:$J$200,MATCH(Graphs!T$1,'Stats 2020'!$D$18:$J$18,0),0) -> 1 | U22: =VLOOKUP($B22,'Stats 2020'!$D$25:$J$200,MATCH(Graphs!U$1,'Stats 2020'!$D$18:$J$18,0),0) -> 1 | V22: =VLOOKUP($B22,'Stats 2020'!$D$25:$J$200,MATCH(Graphs!V$1,'Stats 2020'!$D$18:$J$18,0),0) -> 1 | X22: =B22 -> 43994 | Y22: =SUM(Q$2:Q22)/COUNTA($P$2:$P22) -> 0.9047619 | Z22: =SUM(R$2:R22)/COUNTA($P$2:$P22) -> 0.047619048 | AA22: =SUM(S$2:S22)/COUNTA($P$2:$P22) -> 0.85714286 | AB22: =SUM(T$2:T22)/COUNTA($P$2:$P22) -> 0.28571429 | AC22: =SUM(U$2:U22)/COUNTA($P$2:$P22) -> 0.80952381 | AD22: =SUM(V$2:V22)/COUNTA($P$2:$P22) -> 0.85714286 | AE22: =AVERAGE(Y22:AD22) -> 0.62698413 | AF22: =VLOOKUP($A22,$X$1:$AE$59,MATCH(AF$1,$X$1:$AE$1,0),0) -> #N/A | AG22: =VLOOKUP($A22,$X$1:$AE$59,MATCH(AG$1,$X$1:$AE$1,0),0) -> #N/A | AH22: =VLOOKUP($A22,$X$1:$AE$59,MATCH(AH$1,$X$1:$AE$1,0),0) -> #N/A | AI22: =VLOOKUP($A22,$X$1:$AE$59,MATCH(AI$1,$X$1:$AE$1,0),0) -> #N/A | AJ22: =VLOOKUP($A22,$X$1:$AE$59,MATCH(AJ$1,$X$1:$AE$1,0),0) -> #N/A | AK22: =VLOOKUP($A22,$X$1:$AE$59,MATCH(AK$1,$X$1:$AE$1,0),0) -> #N/A | AL22: =VLOOKUP($A22,$X$1:$AE$59,MATCH(AL$1,$X$1:$AE$1,0),0) -> #N/A
A23: =IF(AND((TODAY()-B23)<7,(TODAY()-B23>=0)),B23,NA()) -> #N/A | B23: =B22+7 -> 44001 | C23: =IF($B23<=TODAY(),SUMIF('Stats 2020'!$M$24:$M$1048576,"<="&Graphs!$B23,'Stats 2020'!O$24:O$1048576),NA()) -> 88.5 | D23: =IF($B23<=TODAY(),MAX($C23,$E23,$G23,$H23)+11+16.5,NA()) -> 116 | E23: =IF($B23<=TODAY(),SUMIF('Stats 2020'!$M$24:$M$1048576,"<="&Graphs!$B23,'Stats 2020'!Q$24:Q$1048576),NA()) -> 72 | F23: =IF($B23<=TODAY(),MAX($C23,$E23,$G23,$H23)+11+16.5,NA()) -> 116 | G23: =IF($B23<=TODAY(),SUMIF('Stats 2020'!$M$24:$M$1048576,"<="&Graphs!$B23,'Stats 2020'!S$24:S$1048576),NA()) -> 88.5 | H23: =IF($B23<=TODAY(),SUMIF('Stats 2020'!$M$24:$M$1048576,"<="&Graphs!$B23,'Stats 2020'!T$24:T$1048576),NA()) -> 74.75 | I23: =VLOOKUP($A23,$B$1:$H$59,MATCH(I$1,$B$1:$H$1,0),0) -> #N/A | J23: =VLOOKUP($A23,$B$1:$H$59,MATCH(J$1,$B$1:$H$1,0),0) -> #N/A | K23: =VLOOKUP($A23,$B$1:$H$59,MATCH(K$1,$B$1:$H$1,0),0) -> #N/A | L23: =VLOOKUP($A23,$B$1:$H$59,MATCH(L$1,$B$1:$H$1,0),0) -> #N/A | M23: =VLOOKUP($A23,$B$1:$H$59,MATCH(M$1,$B$1:$H$1,0),0) -> #N/A | N23: =VLOOKUP($A23,$B$1:$H$59,MATCH(N$1,$B$1:$H$1,0),0) -> #N/A | P23: =B23 -> 44001 | Q23: =VLOOKUP($B23,'Stats 2020'!$D$25:$J$200,MATCH(Graphs!Q$1,'Stats 2020'!$D$18:$J$18,0),0) -> 0 | R23: =VLOOKUP($B23,'Stats 2020'!$D$25:$J$200,MATCH(Graphs!R$1,'Stats 2020'!$D$18:$J$18,0),0) | S23: =VLOOKUP($B23,'Stats 2020'!$D$25:$J$200,MATCH(Graphs!S$1,'Stats 2020'!$D$18:$J$18,0),0) -> 1 | T23: =VLOOKUP($B23,'Stats 2020'!$D$25:$J$200,MATCH(Graphs!T$1,'Stats 2020'!$D$18:$J$18,0),0) -> 1 | U23: =VLOOKUP($B23,'Stats 2020'!$D$25:$J$200,MATCH(Graphs!U$1,'Stats 2020'!$D$18:$J$18,0),0) -> 1 | V23: =VLOOKUP($B23,'Stats 2020'!$D$25:$J$200,MATCH(Graphs!V$1,'Stats 2020'!$D$18:$J$18,0),0) -> 1 | X23: =B23 -> 44001 | Y23: =SUM(Q$2:Q23)/COUNTA($P$2:$P23) -> 0.86363636 | Z23: =SUM(R$2:R23)/COUNTA($P$2:$P23) -> 0.045454545 | AA23: =SUM(S$2:S23)/COUNTA($P$2:$P23) -> 0.86363636 | AB23: =SUM(T$2:T23)/COUNTA($P$2:$P23) -> 0.31818182 | AC23: =SUM(U$2:U23)/COUNTA($P$2:$P23) -> 0.81818182 | AD23: =SUM(V$2:V23)/COUNTA($P$2:$P23) -> 0.86363636 | AE23: =AVERAGE(Y23:AD23) -> 0.62878788 | AF23: =VLOOKUP($A23,$X$1:$AE$59,MATCH(AF$1,$X$1:$AE$1,0),0) -> #N/A | AG23: =VLOOKUP($A23,$X$1:$AE$59,MATCH(AG$1,$X$1:$AE$1,0),0) -> #N/A | AH23: =VLOOKUP($A23,$X$1:$AE$59,MATCH(AH$1,$X$1:$AE$1,0),0) -> #N/A | AI23: =VLOOKUP($A23,$X$1:$AE$59,MATCH(AI$1,$X$1:$AE$1,0),0) -> #N/A | AJ23: =VLOOKUP($A23,$X$1:$AE$59,MATCH(AJ$1,$X$1:$AE$1,0),0) -> #N/A | AK23: =VLOOKUP($A23,$X$1:$AE$59,MATCH(AK$1,$X$1:$AE$1,0),0) -> #N/A | AL23: =VLOOKUP($A23,$X$1:$AE$59,MATCH(AL$1,$X$1:$AE$1,0),0) -> #N/A
